Workbook

Sheet Wedstrijden_beheer
A1: Tijd | B1: Thuis | C1: Uitslag | D1: Uit | E1: Roland | G1: Nikki | I1: Abdussamed | K1: Karsten | M1: Bas | O1: Maik | Q1: Simone | S1: Marc | U1: Tom | W1: Jos | Y1: Lesley | AA1: Ivo | AC1: Ron | AE1: Jeroen | AG1: Erwin | AI1: Tim | AK1: Kim | AM1: Kristel | AO1: Patrick | AQ1: Jeno | AS1: Andre | AU1: Raymond | AW1: _ActThuis | AX1: _ActUit
E2: Voorspelling | F2: Punten | G2: Voorspelling | H2: Punten | I2: Voorspelling | J2: Punten | K2: Voorspelling | L2: Punten | M2: Voorspelling | N2: Punten | O2: Voorspelling | P2: Punten | Q2: Voorspelling | R2: Punten | S2: Voorspelling | T2: Punten | U2: Voorspelling | V2: Punten | W2: Voorspelling | X2: Punten | Y2: Voorspelling | Z2: Punten | AA2: Voorspelling | AB2: Punten | AC2: Voorspelling | AD2: Punten | AE2: Voorspelling | AF2: Punten | AG2: Voorspelling | AH2: Punten | AI2: Voorspelling | AJ2: Punten | AK2: Voorspelling | AL2: Punten | AM2: Voorspelling | AN2: Punten | AO2: Voorspelling | AP2: Punten | AQ2: Voorspelling | AR2: Punten | AS2: Voorspelling | AT2: Punten | AU2: Voorspelling | AV2: Punten | AW2: _ActThuis | AX2: _ActUit
A3: Groepsfase
A4: donderdag 11 juni 2026
A5: 1.875 | B5: Mexico | C5: 2-0 | D5: Zuid-Afrika | E5: 2-1 | F5: =IF(OR($C5="",E5=""),"",IFERROR(IF(AND(IFERROR(--LEFT(E5,FIND("-",E5)-1),"")=AW5,IFERROR(--MID(E5,FIND("-",E5)+1,99),"")=AX5),10,5*(SIGN((IFERROR(--LEFT(E5,FIND("-",E5)-1),""))-(IFERROR(--MID(E5,FIND("-",E5)+1,99),"")))=SIGN((AW5)-(AX5)))+2*(((IFERROR(--LEFT(E5,FIND("-",E5)-1),""))-(IFERROR(--MID(E5,FIND("-",E5)+1,99),"")))=((AW5)-(AX5)))+2*((IFERROR(--LEFT(E5,FIND("-",E5)-1),""))=(AW5))+2*((IFERROR(--MID(E5,FIND("-",E5)+1,99),""))=(AX5))),"")) -> 7 | G5: 3-1 | H5: =IF(OR($C5="",G5=""),"",IFERROR(IF(AND(IFERROR(--LEFT(G5,FIND("-",G5)-1),"")=AW5,IFERROR(--MID(G5,FIND("-",G5)+1,99),"")=AX5),10,5*(SIGN((IFERROR(--LEFT(G5,FIND("-",G5)-1),""))-(IFERROR(--MID(G5,FIND("-",G5)+1,99),"")))=SIGN((AW5)-(AX5)))+2*(((IFERROR(--LEFT(G5,FIND("-",G5)-1),""))-(IFERROR(--MID(G5,FIND("-",G5)+1,99),"")))=((AW5)-(AX5)))+2*((IFERROR(--LEFT(G5,FIND("-",G5)-1),""))=(AW5))+2*((IFERROR(--MID(G5,FIND("-",G5)+1,99),""))=(AX5))),"")) -> 7 | I5: 1-1 | J5: =IF(OR($C5="",I5=""),"",IFERROR(IF(AND(IFERROR(--LEFT(I5,FIND("-",I5)-1),"")=AW5,IFERROR(--MID(I5,FIND("-",I5)+1,99),"")=AX5),10,5*(SIGN((IFERROR(--LEFT(I5,FIND("-",I5)-1),""))-(IFERROR(--MID(I5,FIND("-",I5)+1,99),"")))=SIGN((AW5)-(AX5)))+2*(((IFERROR(--LEFT(I5,FIND("-",I5)-1),""))-(IFERROR(--MID(I5,FIND("-",I5)+1,99),"")))=((AW5)-(AX5)))+2*((IFERROR(--LEFT(I5,FIND("-",I5)-1),""))=(AW5))+2*((IFERROR(--MID(I5,FIND("-",I5)+1,99),""))=(AX5))),"")) -> 0 | K5: 2-0 | L5: =IF(OR($C5="",K5=""),"",IFERROR(IF(AND(IFERROR(--LEFT(K5,FIND("-",K5)-1),"")=AW5,IFERROR(--MID(K5,FIND("-",K5)+1,99),"")=AX5),10,5*(SIGN((IFERROR(--LEFT(K5,FIND("-",K5)-1),""))-(IFERROR(--MID(K5,FIND("-",K5)+1,99),"")))=SIGN((AW5)-(AX5)))+2*(((IFERROR(--LEFT(K5,FIND("-",K5)-1),""))-(IFERROR(--MID(K5,FIND("-",K5)+1,99),"")))=((AW5)-(AX5)))+2*((IFERROR(--LEFT(K5,FIND("-",K5)-1),""))=(AW5))+2*((IFERROR(--MID(K5,FIND("-",K5)+1,99),""))=(AX5))),"")) -> 10 | M5: 2-1 | N5: =IF(OR($C5="",M5=""),"",IFERROR(IF(AND(IFERROR(--LEFT(M5,FIND("-",M5)-1),"")=AW5,IFERROR(--MID(M5,FIND("-",M5)+1,99),"")=AX5),10,5*(SIGN((IFERROR(--LEFT(M5,FIND("-",M5)-1),""))-(IFERROR(--MID(M5,FIND("-",M5)+1,99),"")))=SIGN((AW5)-(AX5)))+2*(((IFERROR(--LEFT(M5,FIND("-",M5)-1),""))-(IFERROR(--MID(M5,FIND("-",M5)+1,99),"")))=((AW5)-(AX5)))+2*((IFERROR(--LEFT(M5,FIND("-",M5)-1),""))=(AW5))+2*((IFERROR(--MID(M5,FIND("-",M5)+1,99),""))=(AX5))),"")) -> 7 | O5: 2-0 | P5: =IF(OR($C5="",O5=""),"",IFERROR(IF(AND(IFERROR(--LEFT(O5,FIND("-",O5)-1),"")=AW5,IFERROR(--MID(O5,FIND("-",O5)+1,99),"")=AX5),10,5*(SIGN((IFERROR(--LEFT(O5,FIND("-",O5)-1),""))-(IFERROR(--MID(O5,FIND("-",O5)+1,99),"")))=SIGN((AW5)-(AX5)))+2*(((IFERROR(--LEFT(O5,FIND("-",O5)-1),""))-(IFERROR(--MID(O5,FIND("-",O5)+1,99),"")))=((AW5)-(AX5)))+2*((IFERROR(--LEFT(O5,FIND("-",O5)-1),""))=(AW5))+2*((IFERROR(--MID(O5,FIND("-",O5)+1,99),""))=(AX5))),"")) -> 10 | Q5: 1-2 | R5: =IF(OR($C5="",Q5=""),"",IFERROR(IF(AND(IFERROR(--LEFT(Q5,FIND("-",Q5)-1),"")=AW5,IFERROR(--MID(Q5,FIND("-",Q5)+1,99),"")=AX5),10,5*(SIGN((IFERROR(--LEFT(Q5,FIND("-",Q5)-1),""))-(IFERROR(--MID(Q5,FIND("-",Q5)+1,99),"")))=SIGN((AW5)-(AX5)))+2*(((IFERROR(--LEFT(Q5,FIND("-",Q5)-1),""))-(IFERROR(--MID(Q5,FIND("-",Q5)+1,99),"")))=((AW5)-(AX5)))+2*((IFERROR(--LEFT(Q5,FIND("-",Q5)-1),""))=(AW5))+2*((IFERROR(--MID(Q5,FIND("-",Q5)+1,99),""))=(AX5))),"")) -> 0 | S5: 3-1 | T5: =IF(OR($C5="",S5=""),"",IFERROR(IF(AND(IFERROR(--LEFT(S5,FIND("-",S5)-1),"")=AW5,IFERROR(--MID(S5,FIND("-",S5)+1,99),"")=AX5),10,5*(SIGN((IFERROR(--LEFT(S5,FIND("-",S5)-1),""))-(IFERROR(--MID(S5,FIND("-",S5)+1,99),"")))=SIGN((AW5)-(AX5)))+2*(((IFERROR(--LEFT(S5,FIND("-",S5)-1),""))-(IFERROR(--MID(S5,FIND("-",S5)+1,99),"")))=((AW5)-(AX5)))+2*((IFERROR(--LEFT(S5,FIND("-",S5)-1),""))=(AW5))+2*((IFERROR(--MID(S5,FIND("-",S5)+1,99),""))=(AX5))),"")) -> 7 | U5: 2-0 | V5: =IF(OR($C5="",U5=""),"",IFERROR(IF(AND(IFERROR(--LEFT(U5,FIND("-",U5)-1),"")=AW5,IFERROR(--MID(U5,FIND("-",U5)+1,99),"")=AX5),10,5*(SIGN((IFERROR(--LEFT(U5,FIND("-",U5)-1),""))-(IFERROR(--MID(U5,FIND("-",U5)+1,99),"")))=SIGN((AW5)-(AX5)))+2*(((IFERROR(--LEFT(U5,FIND("-",U5)-1),""))-(IFERROR(--MID(U5,FIND("-",U5)+1,99),"")))=((AW5)-(AX5)))+2*((IFERROR(--LEFT(U5,FIND("-",U5)-1),""))=(AW5))+2*((IFERROR(--MID(U5,FIND("-",U5)+1,99),""))=(AX5))),"")) -> 10 | W5: 2-0 | X5: =IF(OR($C5="",W5=""),"",IFERROR(IF(AND(IFERROR(--LEFT(W5,FIND("-",W5)-1),"")=AW5,IFERROR(--MID(W5,FIND("-",W5)+1,99),"")=AX5),10,5*(SIGN((IFERROR(--LEFT(W5,FIND("-",W5)-1),""))-(IFERROR(--MID(W5,FIND("-",W5)+1,99),"")))=SIGN((AW5)-(AX5)))+2*(((IFERROR(--LEFT(W5,FIND("-",W5)-1),""))-(IFERROR(--MID(W5,FIND("-",W5)+1,99),"")))=((AW5)-(AX5)))+2*((IFERROR(--LEFT(W5,FIND("-",W5)-1),""))=(AW5))+2*((IFERROR(--MID(W5,FIND("-",W5)+1,99),""))=(AX5))),"")) -> 10 | Y5: 2-0 | Z5: =IF(OR($C5="",Y5=""),"",IFERROR(IF(AND(IFERROR(--LEFT(Y5,FIND("-",Y5)-1),"")=AW5,IFERROR(--MID(Y5,FIND("-",Y5)+1,99),"")=AX5),10,5*(SIGN((IFERROR(--LEFT(Y5,FIND("-",Y5)-1),""))-(IFERROR(--MID(Y5,FIND("-",Y5)+1,99),"")))=SIGN((AW5)-(AX5)))+2*(((IFERROR(--LEFT(Y5,FIND("-",Y5)-1),""))-(IFERROR(--MID(Y5,FIND("-",Y5)+1,99),"")))=((AW5)-(AX5)))+2*((IFERROR(--LEFT(Y5,FIND("-",Y5)-1),""))=(AW5))+2*((IFERROR(--MID(Y5,FIND("-",Y5)+1,99),""))=(AX5))),"")) -> 10 | AA5: 2-1 | AB5: =IF(OR($C5="",AA5=""),"",IFERROR(IF(AND(IFERROR(--LEFT(AA5,FIND("-",AA5)-1),"")=AW5,IFERROR(--MID(AA5,FIND("-",AA5)+1,99),"")=AX5),10,5*(SIGN((IFERROR(--LEFT(AA5,FIND("-",AA5)-1),""))-(IFERROR(--MID(AA5,FIND("-",AA5)+1,99),"")))=SIGN((AW5)-(AX5)))+2*(((IFERROR(--LEFT(AA5,FIND("-",AA5)-1),""))-(IFERROR(--MID(AA5,FIND("-",AA5)+1,99),"")))=((AW5)-(AX5)))+2*((IFERROR(--LEFT(AA5,FIND("-",AA5)-1),""))=(AW5))+2*((IFERROR(--MID(AA5,FIND("-",AA5)+1,99),""))=(AX5))),"")) -> 7 | AC5: 2-1 | AD5: =IF(OR($C5="",AC5=""),"",IFERROR(IF(AND(IFERROR(--LEFT(AC5,FIND("-",AC5)-1),"")=AW5,IFERROR(--MID(AC5,FIND("-",AC5)+1,99),"")=AX5),10,5*(SIGN((IFERROR(--LEFT(AC5,FIND("-",AC5)-1),""))-(IFERROR(--MID(AC5,FIND("-",AC5)+1,99),"")))=SIGN((AW5)-(AX5)))+2*(((IFERROR(--LEFT(AC5,FIND("-",AC5)-1),""))-(IFERROR(--MID(AC5,FIND("-",AC5)+1,99),"")))=((AW5)-(AX5)))+2*((IFERROR(--LEFT(AC5,FIND("-",AC5)-1),""))=(AW5))+2*((IFERROR(--MID(AC5,FIND("-",AC5)+1,99),""))=(AX5))),"")) -> 7 | AE5: 2-1 | AF5: =IF(OR($C5="",AE5=""),"",IFERROR(IF(AND(IFERROR(--LEFT(AE5,FIND("-",AE5)-1),"")=AW5,IFERROR(--MID(AE5,FIND("-",AE5)+1,99),"")=AX5),10,5*(SIGN((IFERROR(--LEFT(AE5,FIND("-",AE5)-1),""))-(IFERROR(--MID(AE5,FIND("-",AE5)+1,99),"")))=SIGN((AW5)-(AX5)))+2*(((IFERROR(--LEFT(AE5,FIND("-",AE5)-1),""))-(IFERROR(--MID(AE5,FIND("-",AE5)+1,99),"")))=((AW5)-(AX5)))+2*((IFERROR(--LEFT(AE5,FIND("-",AE5)-1),""))=(AW5))+2*((IFERROR(--MID(AE5,FIND("-",AE5)+1,99),""))=(AX5))),"")) -> 7 | AG5: 2-0 | AH5: =IF(OR($C5="",AG5=""),"",IFERROR(IF(AND(IFERROR(--LEFT(AG5,FIND("-",AG5)-1),"")=AW5,IFERROR(--MID(AG5,FIND("-",AG5)+1,99),"")=AX5),10,5*(SIGN((IFERROR(--LEFT(AG5,FIND("-",AG5)-1),""))-(IFERROR(--MID(AG5,FIND("-",AG5)+1,99),"")))=SIGN((AW5)-(AX5)))+2*(((IFERROR(--LEFT(AG5,FIND("-",AG5)-1),""))-(IFERROR(--MID(AG5,FIND("-",AG5)+1,99),"")))=((AW5)-(AX5)))+2*((IFERROR(--LEFT(AG5,FIND("-",AG5)-1),""))=(AW5))+2*((IFERROR(--MID(AG5,FIND("-",AG5)+1,99),""))=(AX5))),"")) -> 10 | AI5: 3-1 | AJ5: =IF(OR($C5="",AI5=""),"",IFERROR(IF(AND(IFERROR(--LEFT(AI5,FIND("-",AI5)-1),"")=AW5,IFERROR(--MID(AI5,FIND("-",AI5)+1,99),"")=AX5),10,5*(SIGN((IFERROR(--LEFT(AI5,FIND("-",AI5)-1),""))-(IFERROR(--MID(AI5,FIND("-",AI5)+1,99),"")))=SIGN((AW5)-(AX5)))+2*(((IFERROR(--LEFT(AI5,FIND("-",AI5)-1),""))-(IFERROR(--MID(AI5,FIND("-",AI5)+1,99),"")))=((AW5)-(AX5)))+2*((IFERROR(--LEFT(AI5,FIND("-",AI5)-1),""))=(AW5))+2*((IFERROR(--MID(AI5,FIND("-",AI5)+1,99),""))=(AX5))),"")) -> 7 | AK5: 2-0 | AL5: =IF(OR($C5="",AK5=""),"",IFERROR(IF(AND(IFERROR(--LEFT(AK5,FIND("-",AK5)-1),"")=AW5,IFERROR(--MID(AK5,FIND("-",AK5)+1,99),"")=AX5),10,5*(SIGN((IFERROR(--LEFT(AK5,FIND("-",AK5)-1),""))-(IFERROR(--MID(AK5,FIND("-",AK5)+1,99),"")))=SIGN((AW5)-(AX5)))+2*(((IFERROR(--LEFT(AK5,FIND("-",AK5)-1),""))-(IFERROR(--MID(AK5,FIND("-",AK5)+1,99),"")))=((AW5)-(AX5)))+2*((IFERROR(--LEFT(AK5,FIND("-",AK5)-1),""))=(AW5))+2*((IFERROR(--MID(AK5,FIND("-",AK5)+1,99),""))=(AX5))),"")) -> 10 | AM5: 3-0 | AN5: =IF(OR($C5="",AM5=""),"",IFERROR(IF(AND(IFERROR(--LEFT(AM5,FIND("-",AM5)-1),"")=AW5,IFERROR(--MID(AM5,FIND("-",AM5)+1,99),"")=AX5),10,5*(SIGN((IFERROR(--LEFT(AM5,FIND("-",AM5)-1),""))-(IFERROR(--MID(AM5,FIND("-",AM5)+1,99),"")))=SIGN((AW5)-(AX5)))+2*(((IFERROR(--LEFT(AM5,FIND("-",AM5)-1),""))-(IFERROR(--MID(AM5,FIND("-",AM5)+1,99),"")))=((AW5)-(AX5)))+2*((IFERROR(--LEFT(AM5,FIND("-",AM5)-1),""))=(AW5))+2*((IFERROR(--MID(AM5,FIND("-",AM5)+1,99),""))=(AX5))),"")) -> 7 | AO5: 3-1 | AP5: =IF(OR($C5="",AO5=""),"",IFERROR(IF(AND(IFERROR(--LEFT(AO5,FIND("-",AO5)-1),"")=AW5,IFERROR(--MID(AO5,FIND("-",AO5)+1,99),"")=AX5),10,5*(SIGN((IFERROR(--LEFT(AO5,FIND("-",AO5)-1),""))-(IFERROR(--MID(AO5,FIND("-",AO5)+1,99),"")))=SIGN((AW5)-(AX5)))+2*(((IFERROR(--LEFT(AO5,FIND("-",AO5)-1),""))-(IFERROR(--MID(AO5,FIND("-",AO5)+1,99),"")))=((AW5)-(AX5)))+2*((IFERROR(--LEFT(AO5,FIND("-",AO5)-1),""))=(AW5))+2*((IFERROR(--MID(AO5,FIND("-",AO5)+1,99),""))=(AX5))),"")) -> 7 | AQ5: 2-0 | AR5: =IF(OR($C5="",AQ5=""),"",IFERROR(IF(AND(IFERROR(--LEFT(AQ5,FIND("-",AQ5)-1),"")=AW5,IFERROR(--MID(AQ5,FIND("-",AQ5)+1,99),"")=AX5),10,5*(SIGN((IFERROR(--LEFT(AQ5,FIND("-",AQ5)-1),""))-(IFERROR(--MID(AQ5,FIND("-",AQ5)+1,99),"")))=SIGN((AW5)-(AX5)))+2*(((IFERROR(--LEFT(AQ5,FIND("-",AQ5)-1),""))-(IFERROR(--MID(AQ5,FIND("-",AQ5)+1,99),"")))=((AW5)-(AX5)))+2*((IFERROR(--LEFT(AQ5,FIND("-",AQ5)-1),""))=(AW5))+2*((IFERROR(--MID(AQ5,FIND("-",AQ5)+1,99),""))=(AX5))),"")) -> 10 | AS5: 2-1 | AT5: =IF(OR($C5="",AS5=""),"",IFERROR(IF(AND(IFERROR(--LEFT(AS5,FIND("-",AS5)-1),"")=AW5,IFERROR(--MID(AS5,FIND("-",AS5)+1,99),"")=AX5),10,5*(SIGN((IFERROR(--LEFT(AS5,FIND("-",AS5)-1),""))-(IFERROR(--MID(AS5,FIND("-",AS5)+1,99),"")))=SIGN((AW5)-(AX5)))+2*(((IFERROR(--LEFT(AS5,FIND("-",AS5)-1),""))-(IFERROR(--MID(AS5,FIND("-",AS5)+1,99),"")))=((AW5)-(AX5)))+2*((IFERROR(--LEFT(AS5,FIND("-",AS5)-1),""))=(AW5))+2*((IFERROR(--MID(AS5,FIND("-",AS5)+1,99),""))=(AX5))),"")) -> 7 | AU5: 1-0 | AV5: =IF(OR($C5="",AU5=""),"",IFERROR(IF(AND(IFERROR(--LEFT(AU5,FIND("-",AU5)-1),"")=AW5,IFERROR(--MID(AU5,FIND("-",AU5)+1,99),"")=AX5),10,5*(SIGN((IFERROR(--LEFT(AU5,FIND("-",AU5)-1),""))-(IFERROR(--MID(AU5,FIND("-",AU5)+1,99),"")))=SIGN((AW5)-(AX5)))+2*(((IFERROR(--LEFT(AU5,FIND("-",AU5)-1),""))-(IFERROR(--MID(AU5,FIND("-",AU5)+1,99),"")))=((AW5)-(AX5)))+2*((IFERROR(--LEFT(AU5,FIND("-",AU5)-1),""))=(AW5))+2*((IFERROR(--MID(AU5,FIND("-",AU5)+1,99),""))=(AX5))),"")) -> 7 | AW5: =IF($C5="","",IFERROR(--LEFT($C5,FIND("-",$C5)-1),"")) -> 2 | AX5: =IF($C5="","",IFERROR(--MID($C5,FIND("-",$C5)+1,99),"")) -> 0
AR6: =IF(OR($C6="",AQ6=""),"",IFERROR(IF(AND(IFERROR(--LEFT(AQ6,FIND("-",AQ6)-1),"")=AW6,IFERROR(--MID(AQ6,FIND("-",AQ6)+1,99),"")=AX6),10,5*(SIGN((IFERROR(--LEFT(AQ6,FIND("-",AQ6)-1),""))-(IFERROR(--MID(AQ6,FIND("-",AQ6)+1,99),"")))=SIGN((AW6)-(AX6)))+2*(((IFERROR(--LEFT(AQ6,FIND("-",AQ6)-1),""))-(IFERROR(--MID(AQ6,FIND("-",AQ6)+1,99),"")))=((AW6)-(AX6)))+2*((IFERROR(--LEFT(AQ6,FIND("-",AQ6)-1),""))=(AW6))+2*((IFERROR(--MID(AQ6,FIND("-",AQ6)+1,99),""))=(AX6))),"")) | AT6: =IF(OR($C6="",AS6=""),"",IFERROR(IF(AND(IFERROR(--LEFT(AS6,FIND("-",AS6)-1),"")=AW6,IFERROR(--MID(AS6,FIND("-",AS6)+1,99),"")=AX6),10,5*(SIGN((IFERROR(--LEFT(AS6,FIND("-",AS6)-1),""))-(IFERROR(--MID(AS6,FIND("-",AS6)+1,99),"")))=SIGN((AW6)-(AX6)))+2*(((IFERROR(--LEFT(AS6,FIND("-",AS6)-1),""))-(IFERROR(--MID(AS6,FIND("-",AS6)+1,99),"")))=((AW6)-(AX6)))+2*((IFERROR(--LEFT(AS6,FIND("-",AS6)-1),""))=(AW6))+2*((IFERROR(--MID(AS6,FIND("-",AS6)+1,99),""))=(AX6))),""))
A7: vrijdag 12 juni 2026
A8: 1.1666667 | B8: Zuid-Korea | C8: 2-1 | D8: Tsjechië | E8: 1-1 | F8: =IF(OR($C8="",E8=""),"",IFERROR(IF(AND(IFERROR(--LEFT(E8,FIND("-",E8)-1),"")=AW8,IFERROR(--MID(E8,FIND("-",E8)+1,99),"")=AX8),10,5*(SIGN((IFERROR(--LEFT(E8,FIND("-",E8)-1),""))-(IFERROR(--MID(E8,FIND("-",E8)+1,99),"")))=SIGN((AW8)-(AX8)))+2*(((IFERROR(--LEFT(E8,FIND("-",E8)-1),""))-(IFERROR(--MID(E8,FIND("-",E8)+1,99),"")))=((AW8)-(AX8)))+2*((IFERROR(--LEFT(E8,FIND("-",E8)-1),""))=(AW8))+2*((IFERROR(--MID(E8,FIND("-",E8)+1,99),""))=(AX8))),"")) -> 2 | G8: 4-1 | H8: =IF(OR($C8="",G8=""),"",IFERROR(IF(AND(IFERROR(--LEFT(G8,FIND("-",G8)-1),"")=AW8,IFERROR(--MID(G8,FIND("-",G8)+1,99),"")=AX8),10,5*(SIGN((IFERROR(--LEFT(G8,FIND("-",G8)-1),""))-(IFERROR(--MID(G8,FIND("-",G8)+1,99),"")))=SIGN((AW8)-(AX8)))+2*(((IFERROR(--LEFT(G8,FIND("-",G8)-1),""))-(IFERROR(--MID(G8,FIND("-",G8)+1,99),"")))=((AW8)-(AX8)))+2*((IFERROR(--LEFT(G8,FIND("-",G8)-1),""))=(AW8))+2*((IFERROR(--MID(G8,FIND("-",G8)+1,99),""))=(AX8))),"")) -> 7 | I8: 1-0 | J8: =IF(OR($C8="",I8=""),"",IFERROR(IF(AND(IFERROR(--LEFT(I8,FIND("-",I8)-1),"")=AW8,IFERROR(--MID(I8,FIND("-",I8)+1,99),"")=AX8),10,5*(SIGN((IFERROR(--LEFT(I8,FIND("-",I8)-1),""))-(IFERROR(--MID(I8,FIND("-",I8)+1,99),"")))=SIGN((AW8)-(AX8)))+2*(((IFERROR(--LEFT(I8,FIND("-",I8)-1),""))-(IFERROR(--MID(I8,FIND("-",I8)+1,99),"")))=((AW8)-(AX8)))+2*((IFERROR(--LEFT(I8,FIND("-",I8)-1),""))=(AW8))+2*((IFERROR(--MID(I8,FIND("-",I8)+1,99),""))=(AX8))),"")) -> 7 | K8: 1-1 | L8: =IF(OR($C8="",K8=""),"",IFERROR(IF(AND(IFERROR(--LEFT(K8,FIND("-",K8)-1),"")=AW8,IFERROR(--MID(K8,FIND("-",K8)+1,99),"")=AX8),10,5*(SIGN((IFERROR(--LEFT(K8,FIND("-",K8)-1),""))-(IFERROR(--MID(K8,FIND("-",K8)+1,99),"")))=SIGN((AW8)-(AX8)))+2*(((IFERROR(--LEFT(K8,FIND("-",K8)-1),""))-(IFERROR(--MID(K8,FIND("-",K8)+1,99),"")))=((AW8)-(AX8)))+2*((IFERROR(--LEFT(K8,FIND("-",K8)-1),""))=(AW8))+2*((IFERROR(--MID(K8,FIND("-",K8)+1,99),""))=(AX8))),"")) -> 2 | M8: 1-2 | N8: =IF(OR($C8="",M8=""),"",IFERROR(IF(AND(IFERROR(--LEFT(M8,FIND("-",M8)-1),"")=AW8,IFERROR(--MID(M8,FIND("-",M8)+1,99),"")=AX8),10,5*(SIGN((IFERROR(--LEFT(M8,FIND("-",M8)-1),""))-(IFERROR(--MID(M8,FIND("-",M8)+1,99),"")))=SIGN((AW8)-(AX8)))+2*(((IFERROR(--LEFT(M8,FIND("-",M8)-1),""))-(IFERROR(--MID(M8,FIND("-",M8)+1,99),"")))=((AW8)-(AX8)))+2*((IFERROR(--LEFT(M8,FIND("-",M8)-1),""))=(AW8))+2*((IFERROR(--MID(M8,FIND("-",M8)+1,99),""))=(AX8))),"")) -> 0 | O8: 1-1 | P8: =IF(OR($C8="",O8=""),"",IFERROR(IF(AND(IFERROR(--LEFT(O8,FIND("-",O8)-1),"")=AW8,IFERROR(--MID(O8,FIND("-",O8)+1,99),"")=AX8),10,5*(SIGN((IFERROR(--LEFT(O8,FIND("-",O8)-1),""))-(IFERROR(--MID(O8,FIND("-",O8)+1,99),"")))=SIGN((AW8)-(AX8)))+2*(((IFERROR(--LEFT(O8,FIND("-",O8)-1),""))-(IFERROR(--MID(O8,FIND("-",O8)+1,99),"")))=((AW8)-(AX8)))+2*((IFERROR(--LEFT(O8,FIND("-",O8)-1),""))=(AW8))+2*((IFERROR(--MID(O8,FIND("-",O8)+1,99),""))=(AX8))),"")) -> 2 | Q8: 2-3 | R8: =IF(OR($C8="",Q8=""),"",IFERROR(IF(AND(IFERROR(--LEFT(Q8,FIND("-",Q8)-1),"")=AW8,IFERROR(--MID(Q8,FIND("-",Q8)+1,99),"")=AX8),10,5*(SIGN((IFERROR(--LEFT(Q8,FIND("-",Q8)-1),""))-(IFERROR(--MID(Q8,FIND("-",Q8)+1,99),"")))=SIGN((AW8)-(AX8)))+2*(((IFERROR(--LEFT(Q8,FIND("-",Q8)-1),""))-(IFERROR(--MID(Q8,FIND("-",Q8)+1,99),"")))=((AW8)-(AX8)))+2*((IFERROR(--LEFT(Q8,FIND("-",Q8)-1),""))=(AW8))+2*((IFERROR(--MID(Q8,FIND("-",Q8)+1,99),""))=(AX8))),"")) -> 2 | S8: 1-1 | T8: =IF(OR($C8="",S8=""),"",IFERROR(IF(AND(IFERROR(--LEFT(S8,FIND("-",S8)-1),"")=AW8,IFERROR(--MID(S8,FIND("-",S8)+1,99),"")=AX8),10,5*(SIGN((IFERROR(--LEFT(S8,FIND("-",S8)-1),""))-(IFERROR(--MID(S8,FIND("-",S8)+1,99),"")))=SIGN((AW8)-(AX8)))+2*(((IFERROR(--LEFT(S8,FIND("-",S8)-1),""))-(IFERROR(--MID(S8,FIND("-",S8)+1,99),"")))=((AW8)-(AX8)))+2*((IFERROR(--LEFT(S8,FIND("-",S8)-1),""))=(AW8))+2*((IFERROR(--MID(S8,FIND("-",S8)+1,99),""))=(AX8))),"")) -> 2 | U8: 1-1 | V8: =IF(OR($C8="",U8=""),"",IFERROR(IF(AND(IFERROR(--LEFT(U8,FIND("-",U8)-1),"")=AW8,IFERROR(--MID(U8,FIND("-",U8)+1,99),"")=AX8),10,5*(SIGN((IFERROR(--LEFT(U8,FIND("-",U8)-1),""))-(IFERROR(--MID(U8,FIND("-",U8)+1,99),"")))=SIGN((AW8)-(AX8)))+2*(((IFERROR(--LEFT(U8,FIND("-",U8)-1),""))-(IFERROR(--MID(U8,FIND("-",U8)+1,99),"")))=((AW8)-(AX8)))+2*((IFERROR(--LEFT(U8,FIND("-",U8)-1),""))=(AW8))+2*((IFERROR(--MID(U8,FIND("-",U8)+1,99),""))=(AX8))),"")) -> 2 | W8: 1-1 | X8: =IF(OR($C8="",W8=""),"",IFERROR(IF(AND(IFERROR(--LEFT(W8,FIND("-",W8)-1),"")=AW8,IFERROR(--MID(W8,FIND("-",W8)+1,99),"")=AX8),10,5*(SIGN((IFERROR(--LEFT(W8,FIND("-",W8)-1),""))-(IFERROR(--MID(W8,FIND("-",W8)+1,99),"")))=SIGN((AW8)-(AX8)))+2*(((IFERROR(--LEFT(W8,FIND("-",W8)-1),""))-(IFERROR(--MID(W8,FIND("-",W8)+1,99),"")))=((AW8)-(AX8)))+2*((IFERROR(--LEFT(W8,FIND("-",W8)-1),""))=(AW8))+2*((IFERROR(--MID(W8,FIND("-",W8)+1,99),""))=(AX8))),"")) -> 2 | Y8: 1-1 | Z8: =IF(OR($C8="",Y8=""),"",IFERROR(IF(AND(IFERROR(--LEFT(Y8,FIND("-",Y8)-1),"")=AW8,IFERROR(--MID(Y8,FIND("-",Y8)+1,99),"")=AX8),10,5*(SIGN((IFERROR(--LEFT(Y8,FIND("-",Y8)-1),""))-(IFERROR(--MID(Y8,FIND("-",Y8)+1,99),"")))=SIGN((AW8)-(AX8)))+2*(((IFERROR(--LEFT(Y8,FIND("-",Y8)-1),""))-(IFERROR(--MID(Y8,FIND("-",Y8)+1,99),"")))=((AW8)-(AX8)))+2*((IFERROR(--LEFT(Y8,FIND("-",Y8)-1),""))=(AW8))+2*((IFERROR(--MID(Y8,FIND("-",Y8)+1,99),""))=(AX8))),"")) -> 2 | AA8: 0-1 | AB8: =IF(OR($C8="",AA8=""),"",IFERROR(IF(AND(IFERROR(--LEFT(AA8,FIND("-",AA8)-1),"")=AW8,IFERROR(--MID(AA8,FIND("-",AA8)+1,99),"")=AX8),10,5*(SIGN((IFERROR(--LEFT(AA8,FIND("-",AA8)-1),""))-(IFERROR(--MID(AA8,FIND("-",AA8)+1,99),"")))=SIGN((AW8)-(AX8)))+2*(((IFERROR(--LEFT(AA8,FIND("-",AA8)-1),""))-(IFERROR(--MID(AA8,FIND("-",AA8)+1,99),"")))=((AW8)-(AX8)))+2*((IFERROR(--LEFT(AA8,FIND("-",AA8)-1),""))=(AW8))+2*((IFERROR(--MID(AA8,FIND("-",AA8)+1,99),""))=(AX8))),"")) -> 2 | AC8: 1-1 | AD8: =IF(OR($C8="",AC8=""),"",IFERROR(IF(AND(IFERROR(--LEFT(AC8,FIND("-",AC8)-1),"")=AW8,IFERROR(--MID(AC8,FIND("-",AC8)+1,99),"")=AX8),10,5*(SIGN((IFERROR(--LEFT(AC8,FIND("-",AC8)-1),""))-(IFERROR(--MID(AC8,FIND("-",AC8)+1,99),"")))=SIGN((AW8)-(AX8)))+2*(((IFERROR(--LEFT(AC8,FIND("-",AC8)-1),""))-(IFERROR(--MID(AC8,FIND("-",AC8)+1,99),"")))=((AW8)-(AX8)))+2*((IFERROR(--LEFT(AC8,FIND("-",AC8)-1),""))=(AW8))+2*((IFERROR(--MID(AC8,FIND("-",AC8)+1,99),""))=(AX8))),"")) -> 2 | AE8: 1-2 | AF8: =IF(OR($C8="",AE8=""),"",IFERROR(IF(AND(IFERROR(--LEFT(AE8,FIND("-",AE8)-1),"")=AW8,IFERROR(--MID(AE8,FIND("-",AE8)+1,99),"")=AX8),10,5*(SIGN((IFERROR(--LEFT(AE8,FIND("-",AE8)-1),""))-(IFERROR(--MID(AE8,FIND("-",AE8)+1,99),"")))=SIGN((AW8)-(AX8)))+2*(((IFERROR(--LEFT(AE8,FIND("-",AE8)-1),""))-(IFERROR(--MID(AE8,FIND("-",AE8)+1,99),"")))=((AW8)-(AX8)))+2*((IFERROR(--LEFT(AE8,FIND("-",AE8)-1),""))=(AW8))+2*((IFERROR(--MID(AE8,FIND("-",AE8)+1,99),""))=(AX8))),"")) -> 0 | AG8: 0-1 | AH8: =IF(OR($C8="",AG8=""),"",IFERROR(IF(AND(IFERROR(--LEFT(AG8,FIND("-",AG8)-1),"")=AW8,IFERROR(--MID(AG8,FIND("-",AG8)+1,99),"")=AX8),10,5*(SIGN((IFERROR(--LEFT(AG8,FIND("-",AG8)-1),""))-(IFERROR(--MID(AG8,FIND("-",AG8)+1,99),"")))=SIGN((AW8)-(AX8)))+2*(((IFERROR(--LEFT(AG8,FIND("-",AG8)-1),""))-(IFERROR(--MID(AG8,FIND("-",AG8)+1,99),"")))=((AW8)-(AX8)))+2*((IFERROR(--LEFT(AG8,FIND("-",AG8)-1),""))=(AW8))+2*((IFERROR(--MID(AG8,FIND("-",AG8)+1,99),""))=(AX8))),"")) -> 2 | AI8: 2-3 | AJ8: =IF(OR($C8="",AI8=""),"",IFERROR(IF(AND(IFERROR(--LEFT(AI8,FIND("-",AI8)-1),"")=AW8,IFERROR(--MID(AI8,FIND("-",AI8)+1,99),"")=AX8),10,5*(SIGN((IFERROR(--LEFT(AI8,FIND("-",AI8)-1),""))-(IFERROR(--MID(AI8,FIND("-",AI8)+1,99),"")))=SIGN((AW8)-(AX8)))+2*(((IFERROR(--LEFT(AI8,FIND("-",AI8)-1),""))-(IFERROR(--MID(AI8,FIND("-",AI8)+1,99),"")))=((AW8)-(AX8)))+2*((IFERROR(--LEFT(AI8,FIND("-",AI8)-1),""))=(AW8))+2*((IFERROR(--MID(AI8,FIND("-",AI8)+1,99),""))=(AX8))),"")) -> 2 | AK8: 1-1 | AL8: =IF(OR($C8="",AK8=""),"",IFERROR(IF(AND(IFERROR(--LEFT(AK8,FIND("-",AK8)-1),"")=AW8,IFERROR(--MID(AK8,FIND("-",AK8)+1,99),"")=AX8),10,5*(SIGN((IFERROR(--LEFT(AK8,FIND("-",AK8)-1),""))-(IFERROR(--MID(AK8,FIND("-",AK8)+1,99),"")))=SIGN((AW8)-(AX8)))+2*(((IFERROR(--LEFT(AK8,FIND("-",AK8)-1),""))-(IFERROR(--MID(AK8,FIND("-",AK8)+1,99),"")))=((AW8)-(AX8)))+2*((IFERROR(--LEFT(AK8,FIND("-",AK8)-1),""))=(AW8))+2*((IFERROR(--MID(AK8,FIND("-",AK8)+1,99),""))=(AX8))),"")) -> 2 | AM8: 2-1 | AN8: =IF(OR($C8="",AM8=""),"",IFERROR(IF(AND(IFERROR(--LEFT(AM8,FIND("-",AM8)-1),"")=AW8,IFERROR(--MID(AM8,FIND("-",AM8)+1,99),"")=AX8),10,5*(SIGN((IFERROR(--LEFT(AM8,FIND("-",AM8)-1),""))-(IFERROR(--MID(AM8,FIND("-",AM8)+1,99),"")))=SIGN((AW8)-(AX8)))+2*(((IFERROR(--LEFT(AM8,FIND("-",AM8)-1),""))-(IFERROR(--MID(AM8,FIND("-",AM8)+1,99),"")))=((AW8)-(AX8)))+2*((IFERROR(--LEFT(AM8,FIND("-",AM8)-1),""))=(AW8))+2*((IFERROR(--MID(AM8,FIND("-",AM8)+1,99),""))=(AX8))),"")) -> 10 | AO8: 1-1 | AP8: =IF(OR($C8="",AO8=""),"",IFERROR(IF(AND(IFERROR(--LEFT(AO8,FIND("-",AO8)-1),"")=AW8,IFERROR(--MID(AO8,FIND("-",AO8)+1,99),"")=AX8),10,5*(SIGN((IFERROR(--LEFT(AO8,FIND("-",AO8)-1),""))-(IFERROR(--MID(AO8,FIND("-",AO8)+1,99),"")))=SIGN((AW8)-(AX8)))+2*(((IFERROR(--LEFT(AO8,FIND("-",AO8)-1),""))-(IFERROR(--MID(AO8,FIND("-",AO8)+1,99),"")))=((AW8)-(AX8)))+2*((IFERROR(--LEFT(AO8,FIND("-",AO8)-1),""))=(AW8))+2*((IFERROR(--MID(AO8,FIND("-",AO8)+1,99),""))=(AX8))),"")) -> 2 | AQ8: 1-1 | AR8: =IF(OR($C8="",AQ8=""),"",IFERROR(IF(AND(IFERROR(--LEFT(AQ8,FIND("-",AQ8)-1),"")=AW8,IFERROR(--MID(AQ8,FIND("-",AQ8)+1,99),"")=AX8),10,5*(SIGN((IFERROR(--LEFT(AQ8,FIND("-",AQ8)-1),""))-(IFERROR(--MID(AQ8,FIND("-",AQ8)+1,99),"")))=SIGN((AW8)-(AX8)))+2*(((IFERROR(--LEFT(AQ8,FIND("-",AQ8)-1),""))-(IFERROR(--MID(AQ8,FIND("-",AQ8)+1,99),"")))=((AW8)-(AX8)))+2*((IFERROR(--LEFT(AQ8,FIND("-",AQ8)-1),""))=(AW8))+2*((IFERROR(--MID(AQ8,FIND("-",AQ8)+1,99),""))=(AX8))),"")) -> 2 | AS8: 2-2 | AT8: =IF(OR($C8="",AS8=""),"",IFERROR(IF(AND(IFERROR(--LEFT(AS8,FIND("-",AS8)-1),"")=AW8,IFERROR(--MID(AS8,FIND("-",AS8)+1,99),"")=AX8),10,5*(SIGN((IFERROR(--LEFT(AS8,FIND("-",AS8)-1),""))-(IFERROR(--MID(AS8,FIND("-",AS8)+1,99),"")))=SIGN((AW8)-(AX8)))+2*(((IFERROR(--LEFT(AS8,FIND("-",AS8)-1),""))-(IFERROR(--MID(AS8,FIND("-",AS8)+1,99),"")))=((AW8)-(AX8)))+2*((IFERROR(--LEFT(AS8,FIND("-",AS8)-1),""))=(AW8))+2*((IFERROR(--MID(AS8,FIND("-",AS8)+1,99),""))=(AX8))),"")) -> 2 | AU8: 1-0 | AV8: =IF(OR($C8="",AU8=""),"",IFERROR(IF(AND(IFERROR(--LEFT(AU8,FIND("-",AU8)-1),"")=AW8,IFERROR(--MID(AU8,FIND("-",AU8)+1,99),"")=AX8),10,5*(SIGN((IFERROR(--LEFT(AU8,FIND("-",AU8)-1),""))-(IFERROR(--MID(AU8,FIND("-",AU8)+1,99),"")))=SIGN((AW8)-(AX8)))+2*(((IFERROR(--LEFT(AU8,FIND("-",AU8)-1),""))-(IFERROR(--MID(AU8,FIND("-",AU8)+1,99),"")))=((AW8)-(AX8)))+2*((IFERROR(--LEFT(AU8,FIND("-",AU8)-1),""))=(AW8))+2*((IFERROR(--MID(AU8,FIND("-",AU8)+1,99),""))=(AX8))),"")) -> 7 | AW8: =IF($C8="","",IFERROR(--LEFT($C8,FIND("-",$C8)-1),"")) -> 2 | AX8: =IF($C8="","",IFERROR(--MID($C8,FIND("-",$C8)+1,99),"")) -> 1
A9: 1.875 | B9: Canada | C9: 1-1 | D9: Bosnië en Herzegovina | E9: 2-0 | F9: =IF(OR($C9="",E9=""),"",IFERROR(IF(AND(IFERROR(--LEFT(E9,FIND("-",E9)-1),"")=AW9,IFERROR(--MID(E9,FIND("-",E9)+1,99),"")=AX9),10,5*(SIGN((IFERROR(--LEFT(E9,FIND("-",E9)-1),""))-(IFERROR(--MID(E9,FIND("-",E9)+1,99),"")))=SIGN((AW9)-(AX9)))+2*(((IFERROR(--LEFT(E9,FIND("-",E9)-1),""))-(IFERROR(--MID(E9,FIND("-",E9)+1,99),"")))=((AW9)-(AX9)))+2*((IFERROR(--LEFT(E9,FIND("-",E9)-1),""))=(AW9))+2*((IFERROR(--MID(E9,FIND("-",E9)+1,99),""))=(AX9))),"")) -> 0 | G9: 0-2 | H9: =IF(OR($C9="",G9=""),"",IFERROR(IF(AND(IFERROR(--LEFT(G9,FIND("-",G9)-1),"")=AW9,IFERROR(--MID(G9,FIND("-",G9)+1,99),"")=AX9),10,5*(SIGN((IFERROR(--LEFT(G9,FIND("-",G9)-1),""))-(IFERROR(--MID(G9,FIND("-",G9)+1,99),"")))=SIGN((AW9)-(AX9)))+2*(((IFERROR(--LEFT(G9,FIND("-",G9)-1),""))-(IFERROR(--MID(G9,FIND("-",G9)+1,99),"")))=((AW9)-(AX9)))+2*((IFERROR(--LEFT(G9,FIND("-",G9)-1),""))=(AW9))+2*((IFERROR(--MID(G9,FIND("-",G9)+1,99),""))=(AX9))),"")) -> 0 | I9: 1-1 | J9: =IF(OR($C9="",I9=""),"",IFERROR(IF(AND(IFERROR(--LEFT(I9,FIND("-",I9)-1),"")=AW9,IFERROR(--MID(I9,FIND("-",I9)+1,99),"")=AX9),10,5*(SIGN((IFERROR(--LEFT(I9,FIND("-",I9)-1),""))-(IFERROR(--MID(I9,FIND("-",I9)+1,99),"")))=SIGN((AW9)-(AX9)))+2*(((IFERROR(--LEFT(I9,FIND("-",I9)-1),""))-(IFERROR(--MID(I9,FIND("-",I9)+1,99),"")))=((AW9)-(AX9)))+2*((IFERROR(--LEFT(I9,FIND("-",I9)-1),""))=(AW9))+2*((IFERROR(--MID(I9,FIND("-",I9)+1,99),""))=(AX9))),"")) -> 10 | K9: 2-0 | L9: =IF(OR($C9="",K9=""),"",IFERROR(IF(AND(IFERROR(--LEFT(K9,FIND("-",K9)-1),"")=AW9,IFERROR(--MID(K9,FIND("-",K9)+1,99),"")=AX9),10,5*(SIGN((IFERROR(--LEFT(K9,FIND("-",K9)-1),""))-(IFERROR(--MID(K9,FIND("-",K9)+1,99),"")))=SIGN((AW9)-(AX9)))+2*(((IFERROR(--LEFT(K9,FIND("-",K9)-1),""))-(IFERROR(--MID(K9,FIND("-",K9)+1,99),"")))=((AW9)-(AX9)))+2*((IFERROR(--LEFT(K9,FIND("-",K9)-1),""))=(AW9))+2*((IFERROR(--MID(K9,FIND("-",K9)+1,99),""))=(AX9))),"")) -> 0 | M9: 2-2 | N9: =IF(OR($C9="",M9=""),"",IFERROR(IF(AND(IFERROR(--LEFT(M9,FIND("-",M9)-1),"")=AW9,IFERROR(--MID(M9,FIND("-",M9)+1,99),"")=AX9),10,5*(SIGN((IFERROR(--LEFT(M9,FIND("-",M9)-1),""))-(IFERROR(--MID(M9,FIND("-",M9)+1,99),"")))=SIGN((AW9)-(AX9)))+2*(((IFERROR(--LEFT(M9,FIND("-",M9)-1),""))-(IFERROR(--MID(M9,FIND("-",M9)+1,99),"")))=((AW9)-(AX9)))+2*((IFERROR(--LEFT(M9,FIND("-",M9)-1),""))=(AW9))+2*((IFERROR(--MID(M9,FIND("-",M9)+1,99),""))=(AX9))),"")) -> 7 | O9: 1-1 | P9: =IF(OR($C9="",O9=""),"",IFERROR(IF(AND(IFERROR(--LEFT(O9,FIND("-",O9)-1),"")=AW9,IFERROR(--MID(O9,FIND("-",O9)+1,99),"")=AX9),10,5*(SIGN((IFERROR(--LEFT(O9,FIND("-",O9)-1),""))-(IFERROR(--MID(O9,FIND("-",O9)+1,99),"")))=SIGN((AW9)-(AX9)))+2*(((IFERROR(--LEFT(O9,FIND("-",O9)-1),""))-(IFERROR(--MID(O9,FIND("-",O9)+1,99),"")))=((AW9)-(AX9)))+2*((IFERROR(--LEFT(O9,FIND("-",O9)-1),""))=(AW9))+2*((IFERROR(--MID(O9,FIND("-",O9)+1,99),""))=(AX9))),"")) -> 10 | Q9: 1-1 | R9: =IF(OR($C9="",Q9=""),"",IFERROR(IF(AND(IFERROR(--LEFT(Q9,FIND("-",Q9)-1),"")=AW9,IFERROR(--MID(Q9,FIND("-",Q9)+1,99),"")=AX9),10,5*(SIGN((IFERROR(--LEFT(Q9,FIND("-",Q9)-1),""))-(IFERROR(--MID(Q9,FIND("-",Q9)+1,99),"")))=SIGN((AW9)-(AX9)))+2*(((IFERROR(--LEFT(Q9,FIND("-",Q9)-1),""))-(IFERROR(--MID(Q9,FIND("-",Q9)+1,99),"")))=((AW9)-(AX9)))+2*((IFERROR(--LEFT(Q9,FIND("-",Q9)-1),""))=(AW9))+2*((IFERROR(--MID(Q9,FIND("-",Q9)+1,99),""))=(AX9))),"")) -> 10 | S9: 2-1 | T9: =IF(OR($C9="",S9=""),"",IFERROR(IF(AND(IFERROR(--LEFT(S9,FIND("-",S9)-1),"")=AW9,IFERROR(--MID(S9,FIND("-",S9)+1,99),"")=AX9),10,5*(SIGN((IFERROR(--LEFT(S9,FIND("-",S9)-1),""))-(IFERROR(--MID(S9,FIND("-",S9)+1,99),"")))=SIGN((AW9)-(AX9)))+2*(((IFERROR(--LEFT(S9,FIND("-",S9)-1),""))-(IFERROR(--MID(S9,FIND("-",S9)+1,99),"")))=((AW9)-(AX9)))+2*((IFERROR(--LEFT(S9,FIND("-",S9)-1),""))=(AW9))+2*((IFERROR(--MID(S9,FIND("-",S9)+1,99),""))=(AX9))),"")) -> 2 | U9: 2-1 | V9: =IF(OR($C9="",U9=""),"",IFERROR(IF(AND(IFERROR(--LEFT(U9,FIND("-",U9)-1),"")=AW9,IFERROR(--MID(U9,FIND("-",U9)+1,99),"")=AX9),10,5*(SIGN((IFERROR(--LEFT(U9,FIND("-",U9)-1),""))-(IFERROR(--MID(U9,FIND("-",U9)+1,99),"")))=SIGN((AW9)-(AX9)))+2*(((IFERROR(--LEFT(U9,FIND("-",U9)-1),""))-(IFERROR(--MID(U9,FIND("-",U9)+1,99),"")))=((AW9)-(AX9)))+2*((IFERROR(--LEFT(U9,FIND("-",U9)-1),""))=(AW9))+2*((IFERROR(--MID(U9,FIND("-",U9)+1,99),""))=(AX9))),"")) -> 2 | W9: 2-1 | X9: =IF(OR($C9="",W9=""),"",IFERROR(IF(AND(IFERROR(--LEFT(W9,FIND("-",W9)-1),"")=AW9,IFERROR(--MID(W9,FIND("-",W9)+1,99),"")=AX9),10,5*(SIGN((IFERROR(--LEFT(W9,FIND("-",W9)-1),""))-(IFERROR(--MID(W9,FIND("-",W9)+1,99),"")))=SIGN((AW9)-(AX9)))+2*(((IFERROR(--LEFT(W9,FIND("-",W9)-1),""))-(IFERROR(--MID(W9,FIND("-",W9)+1,99),"")))=((AW9)-(AX9)))+2*((IFERROR(--LEFT(W9,FIND("-",W9)-1),""))=(AW9))+2*((IFERROR(--MID(W9,FIND("-",W9)+1,99),""))=(AX9))),"")) -> 2 | Y9: 2-1 | Z9: =IF(OR($C9="",Y9=""),"",IFERROR(IF(AND(IFERROR(--LEFT(Y9,FIND("-",Y9)-1),"")=AW9,IFERROR(--MID(Y9,FIND("-",Y9)+1,99),"")=AX9),10,5*(SIGN((IFERROR(--LEFT(Y9,FIND("-",Y9)-1),""))-(IFERROR(--MID(Y9,FIND("-",Y9)+1,99),"")))=SIGN((AW9)-(AX9)))+2*(((IFERROR(--LEFT(Y9,FIND("-",Y9)-1),""))-(IFERROR(--MID(Y9,FIND("-",Y9)+1,99),"")))=((AW9)-(AX9)))+2*((IFERROR(--LEFT(Y9,FIND("-",Y9)-1),""))=(AW9))+2*((IFERROR(--MID(Y9,FIND("-",Y9)+1,99),""))=(AX9))),"")) -> 2 | AA9: 1-1 | AB9: =IF(OR($C9="",AA9=""),"",IFERROR(IF(AND(IFERROR(--LEFT(AA9,FIND("-",AA9)-1),"")=AW9,IFERROR(--MID(AA9,FIND("-",AA9)+1,99),"")=AX9),10,5*(SIGN((IFERROR(--LEFT(AA9,FIND("-",AA9)-1),""))-(IFERROR(--MID(AA9,FIND("-",AA9)+1,99),"")))=SIGN((AW9)-(AX9)))+2*(((IFERROR(--LEFT(AA9,FIND("-",AA9)-1),""))-(IFERROR(--MID(AA9,FIND("-",AA9)+1,99),"")))=((AW9)-(AX9)))+2*((IFERROR(--LEFT(AA9,FIND("-",AA9)-1),""))=(AW9))+2*((IFERROR(--MID(AA9,FIND("-",AA9)+1,99),""))=(AX9))),"")) -> 10 | AC9: 1-2 | AD9: =IF(OR($C9="",AC9=""),"",IFERROR(IF(AND(IFERROR(--LEFT(AC9,FIND("-",AC9)-1),"")=AW9,IFERROR(--MID(AC9,FIND("-",AC9)+1,99),"")=AX9),10,5*(SIGN((IFERROR(--LEFT(AC9,FIND("-",AC9)-1),""))-(IFERROR(--MID(AC9,FIND("-",AC9)+1,99),"")))=SIGN((AW9)-(AX9)))+2*(((IFERROR(--LEFT(AC9,FIND("-",AC9)-1),""))-(IFERROR(--MID(AC9,FIND("-",AC9)+1,99),"")))=((AW9)-(AX9)))+2*((IFERROR(--LEFT(AC9,FIND("-",AC9)-1),""))=(AW9))+2*((IFERROR(--MID(AC9,FIND("-",AC9)+1,99),""))=(AX9))),"")) -> 2 | AE9: 1-1 | AF9: =IF(OR($C9="",AE9=""),"",IFERROR(IF(AND(IFERROR(--LEFT(AE9,FIND("-",AE9)-1),"")=AW9,IFERROR(--MID(AE9,FIND("-",AE9)+1,99),"")=AX9),10,5*(SIGN((IFERROR(--LEFT(AE9,FIND("-",AE9)-1),""))-(IFERROR(--MID(AE9,FIND("-",AE9)+1,99),"")))=SIGN((AW9)-(AX9)))+2*(((IFERROR(--LEFT(AE9,FIND("-",AE9)-1),""))-(IFERROR(--MID(AE9,FIND("-",AE9)+1,99),"")))=((AW9)-(AX9)))+2*((IFERROR(--LEFT(AE9,FIND("-",AE9)-1),""))=(AW9))+2*((IFERROR(--MID(AE9,FIND("-",AE9)+1,99),""))=(AX9))),"")) -> 10 | AG9: 2-0 | AH9: =IF(OR($C9="",AG9=""),"",IFERROR(IF(AND(IFERROR(--LEFT(AG9,FIND("-",AG9)-1),"")=AW9,IFERROR(--MID(AG9,FIND("-",AG9)+1,99),"")=AX9),10,5*(SIGN((IFERROR(--LEFT(AG9,FIND("-",AG9)-1),""))-(IFERROR(--MID(AG9,FIND("-",AG9)+1,99),"")))=SIGN((AW9)-(AX9)))+2*(((IFERROR(--LEFT(AG9,FIND("-",AG9)-1),""))-(IFERROR(--MID(AG9,FIND("-",AG9)+1,99),"")))=((AW9)-(AX9)))+2*((IFERROR(--LEFT(AG9,FIND("-",AG9)-1),""))=(AW9))+2*((IFERROR(--MID(AG9,FIND("-",AG9)+1,99),""))=(AX9))),"")) -> 0 | AI9: 2-0 | AJ9: =IF(OR($C9="",AI9=""),"",IFERROR(IF(AND(IFERROR(--LEFT(AI9,FIND("-",AI9)-1),"")=AW9,IFERROR(--MID(AI9,FIND("-",AI9)+1,99),"")=AX9),10,5*(SIGN((IFERROR(--LEFT(AI9,FIND("-",AI9)-1),""))-(IFERROR(--MID(AI9,FIND("-",AI9)+1,99),"")))=SIGN((AW9)-(AX9)))+2*(((IFERROR(--LEFT(AI9,FIND("-",AI9)-1),""))-(IFERROR(--MID(AI9,FIND("-",AI9)+1,99),"")))=((AW9)-(AX9)))+2*((IFERROR(--LEFT(AI9,FIND("-",AI9)-1),""))=(AW9))+2*((IFERROR(--MID(AI9,FIND("-",AI9)+1,99),""))=(AX9))),"")) -> 0 | AK9: 1-0 | AL9: =IF(OR($C9="",AK9=""),"",IFERROR(IF(AND(IFERROR(--LEFT(AK9,FIND("-",AK9)-1),"")=AW9,IFERROR(--MID(AK9,FIND("-",AK9)+1,99),"")=AX9),10,5*(SIGN((IFERROR(--LEFT(AK9,FIND("-",AK9)-1),""))-(IFERROR(--MID(AK9,FIND("-",AK9)+1,99),"")))=SIGN((AW9)-(AX9)))+2*(((IFERROR(--LEFT(AK9,FIND("-",AK9)-1),""))-(IFERROR(--MID(AK9,FIND("-",AK9)+1,99),"")))=((AW9)-(AX9)))+2*((IFERROR(--LEFT(AK9,FIND("-",AK9)-1),""))=(AW9))+2*((IFERROR(--MID(AK9,FIND("-",AK9)+1,99),""))=(AX9))),"")) -> 2 | AM9: 0-1 | AN9: =IF(OR($C9="",AM9=""),"",IFERROR(IF(AND(IFERROR(--LEFT(AM9,FIND("-",AM9)-1),"")=AW9,IFERROR(--MID(AM9,FIND("-",AM9)+1,99),"")=AX9),10,5*(SIGN((IFERROR(--LEFT(AM9,FIND("-",AM9)-1),""))-(IFERROR(--MID(AM9,FIND("-",AM9)+1,99),"")))=SIGN((AW9)-(AX9)))+2*(((IFERROR(--LEFT(AM9,FIND("-",AM9)-1),""))-(IFERROR(--MID(AM9,FIND("-",AM9)+1,99),"")))=((AW9)-(AX9)))+2*((IFERROR(--LEFT(AM9,FIND("-",AM9)-1),""))=(AW9))+2*((IFERROR(--MID(AM9,FIND("-",AM9)+1,99),""))=(AX9))),"")) -> 2 | AO9: 2-0 | AP9: =IF(OR($C9="",AO9=""),"",IFERROR(IF(AND(IFERROR(--LEFT(AO9,FIND("-",AO9)-1),"")=AW9,IFERROR(--MID(AO9,FIND("-",AO9)+1,99),"")=AX9),10,5*(SIGN((IFERROR(--LEFT(AO9,FIND("-",AO9)-1),""))-(IFERROR(--MID(AO9,FIND("-",AO9)+1,99),"")))=SIGN((AW9)-(AX9)))+2*(((IFERROR(--LEFT(AO9,FIND("-",AO9)-1),""))-(IFERROR(--MID(AO9,FIND("-",AO9)+1,99),"")))=((AW9)-(AX9)))+2*((IFERROR(--LEFT(AO9,FIND("-",AO9)-1),""))=(AW9))+2*((IFERROR(--MID(AO9,FIND("-",AO9)+1,99),""))=(AX9))),"")) -> 0 | AQ9: 1-2 | AR9: =IF(OR($C9="",AQ9=""),"",IFERROR(IF(AND(IFERROR(--LEFT(AQ9,FIND("-",AQ9)-1),"")=AW9,IFERROR(--MID(AQ9,FIND("-",AQ9)+1,99),"")=AX9),10,5*(SIGN((IFERROR(--LEFT(AQ9,FIND("-",AQ9)-1),""))-(IFERROR(--MID(AQ9,FIND("-",AQ9)+1,99),"")))=SIGN((AW9)-(AX9)))+2*(((IFERROR(--LEFT(AQ9,FIND("-",AQ9)-1),""))-(IFERROR(--MID(AQ9,FIND("-",AQ9)+1,99),"")))=((AW9)-(AX9)))+2*((IFERROR(--LEFT(AQ9,FIND("-",AQ9)-1),""))=(AW9))+2*((IFERROR(--MID(AQ9,FIND("-",AQ9)+1,99),""))=(AX9))),"")) -> 2 | AS9: 0-0 | AT9: =IF(OR($C9="",AS9=""),"",IFERROR(IF(AND(IFERROR(--LEFT(AS9,FIND("-",AS9)-1),"")=AW9,IFERROR(--MID(AS9,FIND("-",AS9)+1,99),"")=AX9),10,5*(SIGN((IFERROR(--LEFT(AS9,FIND("-",AS9)-1),""))-(IFERROR(--MID(AS9,FIND("-",AS9)+1,99),"")))=SIGN((AW9)-(AX9)))+2*(((IFERROR(--LEFT(AS9,FIND("-",AS9)-1),""))-(IFERROR(--MID(AS9,FIND("-",AS9)+1,99),"")))=((AW9)-(AX9)))+2*((IFERROR(--LEFT(AS9,FIND("-",AS9)-1),""))=(AW9))+2*((IFERROR(--MID(AS9,FIND("-",AS9)+1,99),""))=(AX9))),"")) -> 7 | AU9: 0-0 | AV9: =IF(OR($C9="",AU9=""),"",IFERROR(IF(AND(IFERROR(--LEFT(AU9,FIND("-",AU9)-1),"")=AW9,IFERROR(--MID(AU9,FIND("-",AU9)+1,99),"")=AX9),10,5*(SIGN((IFERROR(--LEFT(AU9,FIND("-",AU9)-1),""))-(IFERROR(--MID(AU9,FIND("-",AU9)+1,99),"")))=SIGN((AW9)-(AX9)))+2*(((IFERROR(--LEFT(AU9,FIND("-",AU9)-1),""))-(IFERROR(--MID(AU9,FIND("-",AU9)+1,99),"")))=((AW9)-(AX9)))+2*((IFERROR(--LEFT(AU9,FIND("-",AU9)-1),""))=(AW9))+2*((IFERROR(--MID(AU9,FIND("-",AU9)+1,99),""))=(AX9))),"")) -> 7 | AW9: =IF($C9="","",IFERROR(--LEFT($C9,FIND("-",$C9)-1),"")) -> 1 | AX9: =IF($C9="","",IFERROR(--MID($C9,FIND("-",$C9)+1,99),"")) -> 1
AR10: =IF(OR($C10="",AQ10=""),"",IFERROR(IF(AND(IFERROR(--LEFT(AQ10,FIND("-",AQ10)-1),"")=AW10,IFERROR(--MID(AQ10,FIND("-",AQ10)+1,99),"")=AX10),10,5*(SIGN((IFERROR(--LEFT(AQ10,FIND("-",AQ10)-1),""))-(IFERROR(--MID(AQ10,FIND("-",AQ10)+1,99),"")))=SIGN((AW10)-(AX10)))+2*(((IFERROR(--LEFT(AQ10,FIND("-",AQ10)-1),""))-(IFERROR(--MID(AQ10,FIND("-",AQ10)+1,99),"")))=((AW10)-(AX10)))+2*((IFERROR(--LEFT(AQ10,FIND("-",AQ10)-1),""))=(AW10))+2*((IFERROR(--MID(AQ10,FIND("-",AQ10)+1,99),""))=(AX10))),"")) | AT10: =IF(OR($C10="",AS10=""),"",IFERROR(IF(AND(IFERROR(--LEFT(AS10,FIND("-",AS10)-1),"")=AW10,IFERROR(--MID(AS10,FIND("-",AS10)+1,99),"")=AX10),10,5*(SIGN((IFERROR(--LEFT(AS10,FIND("-",AS10)-1),""))-(IFERROR(--MID(AS10,FIND("-",AS10)+1,99),"")))=SIGN((AW10)-(AX10)))+2*(((IFERROR(--LEFT(AS10,FIND("-",AS10)-1),""))-(IFERROR(--MID(AS10,FIND("-",AS10)+1,99),"")))=((AW10)-(AX10)))+2*((IFERROR(--LEFT(AS10,FIND("-",AS10)-1),""))=(AW10))+2*((IFERROR(--MID(AS10,FIND("-",AS10)+1,99),""))=(AX10))),""))
A11: zaterdag 13 juni 2026
A12: 1.125 | B12: Verenigde Staten | C12: 4-1 | D12: Paraguay | E12: 1-0 | F12: =IF(OR($C12="",E12=""),"",IFERROR(IF(AND(IFERROR(--LEFT(E12,FIND("-",E12)-1),"")=AW12,IFERROR(--MID(E12,FIND("-",E12)+1,99),"")=AX12),10,5*(SIGN((IFERROR(--LEFT(E12,FIND("-",E12)-1),""))-(IFERROR(--MID(E12,FIND("-",E12)+1,99),"")))=SIGN((AW12)-(AX12)))+2*(((IFERROR(--LEFT(E12,FIND("-",E12)-1),""))-(IFERROR(--MID(E12,FIND("-",E12)+1,99),"")))=((AW12)-(AX12)))+2*((IFERROR(--LEFT(E12,FIND("-",E12)-1),""))=(AW12))+2*((IFERROR(--MID(E12,FIND("-",E12)+1,99),""))=(AX12))),"")) -> 5 | G12: 1-2 | H12: =IF(OR($C12="",G12=""),"",IFERROR(IF(AND(IFERROR(--LEFT(G12,FIND("-",G12)-1),"")=AW12,IFERROR(--MID(G12,FIND("-",G12)+1,99),"")=AX12),10,5*(SIGN((IFERROR(--LEFT(G12,FIND("-",G12)-1),""))-(IFERROR(--MID(G12,FIND("-",G12)+1,99),"")))=SIGN((AW12)-(AX12)))+2*(((IFERROR(--LEFT(G12,FIND("-",G12)-1),""))-(IFERROR(--MID(G12,FIND("-",G12)+1,99),"")))=((AW12)-(AX12)))+2*((IFERROR(--LEFT(G12,FIND("-",G12)-1),""))=(AW12))+2*((IFERROR(--MID(G12,FIND("-",G12)+1,99),""))=(AX12))),"")) -> 0 | I12: 1-2 | J12: =IF(OR($C12="",I12=""),"",IFERROR(IF(AND(IFERROR(--LEFT(I12,FIND("-",I12)-1),"")=AW12,IFERROR(--MID(I12,FIND("-",I12)+1,99),"")=AX12),10,5*(SIGN((IFERROR(--LEFT(I12,FIND("-",I12)-1),""))-(IFERROR(--MID(I12,FIND("-",I12)+1,99),"")))=SIGN((AW12)-(AX12)))+2*(((IFERROR(--LEFT(I12,FIND("-",I12)-1),""))-(IFERROR(--MID(I12,FIND("-",I12)+1,99),"")))=((AW12)-(AX12)))+2*((IFERROR(--LEFT(I12,FIND("-",I12)-1),""))=(AW12))+2*((IFERROR(--MID(I12,FIND("-",I12)+1,99),""))=(AX12))),"")) -> 0 | K12: 3-0 | L12: =IF(OR($C12="",K12=""),"",IFERROR(IF(AND(IFERROR(--LEFT(K12,FIND("-",K12)-1),"")=AW12,IFERROR(--MID(K12,FIND("-",K12)+1,99),"")=AX12),10,5*(SIGN((IFERROR(--LEFT(K12,FIND("-",K12)-1),""))-(IFERROR(--MID(K12,FIND("-",K12)+1,99),"")))=SIGN((AW12)-(AX12)))+2*(((IFERROR(--LEFT(K12,FIND("-",K12)-1),""))-(IFERROR(--MID(K12,FIND("-",K12)+1,99),"")))=((AW12)-(AX12)))+2*((IFERROR(--LEFT(K12,FIND("-",K12)-1),""))=(AW12))+2*((IFERROR(--MID(K12,FIND("-",K12)+1,99),""))=(AX12))),"")) -> 7 | M12: 0-1 | N12: =IF(OR($C12="",M12=""),"",IFERROR(IF(AND(IFERROR(--LEFT(M12,FIND("-",M12)-1),"")=AW12,IFERROR(--MID(M12,FIND("-",M12)+1,99),"")=AX12),10,5*(SIGN((IFERROR(--LEFT(M12,FIND("-",M12)-1),""))-(IFERROR(--MID(M12,FIND("-",M12)+1,99),"")))=SIGN((AW12)-(AX12)))+2*(((IFERROR(--LEFT(M12,FIND("-",M12)-1),""))-(IFERROR(--MID(M12,FIND("-",M12)+1,99),"")))=((AW12)-(AX12)))+2*((IFERROR(--LEFT(M12,FIND("-",M12)-1),""))=(AW12))+2*((IFERROR(--MID(M12,FIND("-",M12)+1,99),""))=(AX12))),"")) -> 2 | O12: 2-1 | P12: =IF(OR($C12="",O12=""),"",IFERROR(IF(AND(IFERROR(--LEFT(O12,FIND("-",O12)-1),"")=AW12,IFERROR(--MID(O12,FIND("-",O12)+1,99),"")=AX12),10,5*(SIGN((IFERROR(--LEFT(O12,FIND("-",O12)-1),""))-(IFERROR(--MID(O12,FIND("-",O12)+1,99),"")))=SIGN((AW12)-(AX12)))+2*(((IFERROR(--LEFT(O12,FIND("-",O12)-1),""))-(IFERROR(--MID(O12,FIND("-",O12)+1,99),"")))=((AW12)-(AX12)))+2*((IFERROR(--LEFT(O12,FIND("-",O12)-1),""))=(AW12))+2*((IFERROR(--MID(O12,FIND("-",O12)+1,99),""))=(AX12))),"")) -> 7 | Q12: 1-0 | R12: =IF(OR($C12="",Q12=""),"",IFERROR(IF(AND(IFERROR(--LEFT(Q12,FIND("-",Q12)-1),"")=AW12,IFERROR(--MID(Q12,FIND("-",Q12)+1,99),"")=AX12),10,5*(SIGN((IFERROR(--LEFT(Q12,FIND("-",Q12)-1),""))-(IFERROR(--MID(Q12,FIND("-",Q12)+1,99),"")))=SIGN((AW12)-(AX12)))+2*(((IFERROR(--LEFT(Q12,FIND("-",Q12)-1),""))-(IFERROR(--MID(Q12,FIND("-",Q12)+1,99),"")))=((AW12)-(AX12)))+2*((IFERROR(--LEFT(Q12,FIND("-",Q12)-1),""))=(AW12))+2*((IFERROR(--MID(Q12,FIND("-",Q12)+1,99),""))=(AX12))),"")) -> 5 | S12: 3-0 | T12: =IF(OR($C12="",S12=""),"",IFERROR(IF(AND(IFERROR(--LEFT(S12,FIND("-",S12)-1),"")=AW12,IFERROR(--MID(S12,FIND("-",S12)+1,99),"")=AX12),10,5*(SIGN((IFERROR(--LEFT(S12,FIND("-",S12)-1),""))-(IFERROR(--MID(S12,FIND("-",S12)+1,99),"")))=SIGN((AW12)-(AX12)))+2*(((IFERROR(--LEFT(S12,FIND("-",S12)-1),""))-(IFERROR(--MID(S12,FIND("-",S12)+1,99),"")))=((AW12)-(AX12)))+2*((IFERROR(--LEFT(S12,FIND("-",S12)-1),""))=(AW12))+2*((IFERROR(--MID(S12,FIND("-",S12)+1,99),""))=(AX12))),"")) -> 7 | U12: 2-1 | V12: =IF(OR($C12="",U12=""),"",IFERROR(IF(AND(IFERROR(--LEFT(U12,FIND("-",U12)-1),"")=AW12,IFERROR(--MID(U12,FIND("-",U12)+1,99),"")=AX12),10,5*(SIGN((IFERROR(--LEFT(U12,FIND("-",U12)-1),""))-(IFERROR(--MID(U12,FIND("-",U12)+1,99),"")))=SIGN((AW12)-(AX12)))+2*(((IFERROR(--LEFT(U12,FIND("-",U12)-1),""))-(IFERROR(--MID(U12,FIND("-",U12)+1,99),"")))=((AW12)-(AX12)))+2*((IFERROR(--LEFT(U12,FIND("-",U12)-1),""))=(AW12))+2*((IFERROR(--MID(U12,FIND("-",U12)+1,99),""))=(AX12))),"")) -> 7 | W12: 2-1 | X12: =IF(OR($C12="",W12=""),"",IFERROR(IF(AND(IFERROR(--LEFT(W12,FIND("-",W12)-1),"")=AW12,IFERROR(--MID(W12,FIND("-",W12)+1,99),"")=AX12),10,5*(SIGN((IFERROR(--LEFT(W12,FIND("-",W12)-1),""))-(IFERROR(--MID(W12,FIND("-",W12)+1,99),"")))=SIGN((AW12)-(AX12)))+2*(((IFERROR(--LEFT(W12,FIND("-",W12)-1),""))-(IFERROR(--MID(W12,FIND("-",W12)+1,99),"")))=((AW12)-(AX12)))+2*((IFERROR(--LEFT(W12,FIND("-",W12)-1),""))=(AW12))+2*((IFERROR(--MID(W12,FIND("-",W12)+1,99),""))=(AX12))),"")) -> 7 | Y12: 2-1 | Z12: =IF(OR($C12="",Y12=""),"",IFERROR(IF(AND(IFERROR(--LEFT(Y12,FIND("-",Y12)-1),"")=AW12,IFERROR(--MID(Y12,FIND("-",Y12)+1,99),"")=AX12),10,5*(SIGN((IFERROR(--LEFT(Y12,FIND("-",Y12)-1),""))-(IFERROR(--MID(Y12,FIND("-",Y12)+1,99),"")))=SIGN((AW12)-(AX12)))+2*(((IFERROR(--LEFT(Y12,FIND("-",Y12)-1),""))-(IFERROR(--MID(Y12,FIND("-",Y12)+1,99),"")))=((AW12)-(AX12)))+2*((IFERROR(--LEFT(Y12,FIND("-",Y12)-1),""))=(AW12))+2*((IFERROR(--MID(Y12,FIND("-",Y12)+1,99),""))=(AX12))),"")) -> 7 | AA12: 3-0 | AB12: =IF(OR($C12="",AA12=""),"",IFERROR(IF(AND(IFERROR(--LEFT(AA12,FIND("-",AA12)-1),"")=AW12,IFERROR(--MID(AA12,FIND("-",AA12)+1,99),"")=AX12),10,5*(SIGN((IFERROR(--LEFT(AA12,FIND("-",AA12)-1),""))-(IFERROR(--MID(AA12,FIND("-",AA12)+1,99),"")))=SIGN((AW12)-(AX12)))+2*(((IFERROR(--LEFT(AA12,FIND("-",AA12)-1),""))-(IFERROR(--MID(AA12,FIND("-",AA12)+1,99),"")))=((AW12)-(AX12)))+2*((IFERROR(--LEFT(AA12,FIND("-",AA12)-1),""))=(AW12))+2*((IFERROR(--MID(AA12,FIND("-",AA12)+1,99),""))=(AX12))),"")) -> 7 | AC12: 2-2 | AD12: =IF(OR($C12="",AC12=""),"",IFERROR(IF(AND(IFERROR(--LEFT(AC12,FIND("-",AC12)-1),"")=AW12,IFERROR(--MID(AC12,FIND("-",AC12)+1,99),"")=AX12),10,5*(SIGN((IFERROR(--LEFT(AC12,FIND("-",AC12)-1),""))-(IFERROR(--MID(AC12,FIND("-",AC12)+1,99),"")))=SIGN((AW12)-(AX12)))+2*(((IFERROR(--LEFT(AC12,FIND("-",AC12)-1),""))-(IFERROR(--MID(AC12,FIND("-",AC12)+1,99),"")))=((AW12)-(AX12)))+2*((IFERROR(--LEFT(AC12,FIND("-",AC12)-1),""))=(AW12))+2*((IFERROR(--MID(AC12,FIND("-",AC12)+1,99),""))=(AX12))),"")) -> 0 | AE12: 2-1 | AF12: =IF(OR($C12="",AE12=""),"",IFERROR(IF(AND(IFERROR(--LEFT(AE12,FIND("-",AE12)-1),"")=AW12,IFERROR(--MID(AE12,FIND("-",AE12)+1,99),"")=AX12),10,5*(SIGN((IFERROR(--LEFT(AE12,FIND("-",AE12)-1),""))-(IFERROR(--MID(AE12,FIND("-",AE12)+1,99),"")))=SIGN((AW12)-(AX12)))+2*(((IFERROR(--LEFT(AE12,FIND("-",AE12)-1),""))-(IFERROR(--MID(AE12,FIND("-",AE12)+1,99),"")))=((AW12)-(AX12)))+2*((IFERROR(--LEFT(AE12,FIND("-",AE12)-1),""))=(AW12))+2*((IFERROR(--MID(AE12,FIND("-",AE12)+1,99),""))=(AX12))),"")) -> 7 | AG12: 3-0 | AH12: =IF(OR($C12="",AG12=""),"",IFERROR(IF(AND(IFERROR(--LEFT(AG12,FIND("-",AG12)-1),"")=AW12,IFERROR(--MID(AG12,FIND("-",AG12)+1,99),"")=AX12),10,5*(SIGN((IFERROR(--LEFT(AG12,FIND("-",AG12)-1),""))-(IFERROR(--MID(AG12,FIND("-",AG12)+1,99),"")))=SIGN((AW12)-(AX12)))+2*(((IFERROR(--LEFT(AG12,FIND("-",AG12)-1),""))-(IFERROR(--MID(AG12,FIND("-",AG12)+1,99),"")))=((AW12)-(AX12)))+2*((IFERROR(--LEFT(AG12,FIND("-",AG12)-1),""))=(AW12))+2*((IFERROR(--MID(AG12,FIND("-",AG12)+1,99),""))=(AX12))),"")) -> 7 | AI12: 1-0 | AJ12: =IF(OR($C12="",AI12=""),"",IFERROR(IF(AND(IFERROR(--LEFT(AI12,FIND("-",AI12)-1),"")=AW12,IFERROR(--MID(AI12,FIND("-",AI12)+1,99),"")=AX12),10,5*(SIGN((IFERROR(--LEFT(AI12,FIND("-",AI12)-1),""))-(IFERROR(--MID(AI12,FIND("-",AI12)+1,99),"")))=SIGN((AW12)-(AX12)))+2*(((IFERROR(--LEFT(AI12,FIND("-",AI12)-1),""))-(IFERROR(--MID(AI12,FIND("-",AI12)+1,99),"")))=((AW12)-(AX12)))+2*((IFERROR(--LEFT(AI12,FIND("-",AI12)-1),""))=(AW12))+2*((IFERROR(--MID(AI12,FIND("-",AI12)+1,99),""))=(AX12))),"")) -> 5 | AK12: 2-1 | AL12: =IF(OR($C12="",AK12=""),"",IFERROR(IF(AND(IFERROR(--LEFT(AK12,FIND("-",AK12)-1),"")=AW12,IFERROR(--MID(AK12,FIND("-",AK12)+1,99),"")=AX12),10,5*(SIGN((IFERROR(--LEFT(AK12,FIND("-",AK12)-1),""))-(IFERROR(--MID(AK12,FIND("-",AK12)+1,99),"")))=SIGN((AW12)-(AX12)))+2*(((IFERROR(--LEFT(AK12,FIND("-",AK12)-1),""))-(IFERROR(--MID(AK12,FIND("-",AK12)+1,99),"")))=((AW12)-(AX12)))+2*((IFERROR(--LEFT(AK12,FIND("-",AK12)-1),""))=(AW12))+2*((IFERROR(--MID(AK12,FIND("-",AK12)+1,99),""))=(AX12))),"")) -> 7 | AM12: 2-0 | AN12: =IF(OR($C12="",AM12=""),"",IFERROR(IF(AND(IFERROR(--LEFT(AM12,FIND("-",AM12)-1),"")=AW12,IFERROR(--MID(AM12,FIND("-",AM12)+1,99),"")=AX12),10,5*(SIGN((IFERROR(--LEFT(AM12,FIND("-",AM12)-1),""))-(IFERROR(--MID(AM12,FIND("-",AM12)+1,99),"")))=SIGN((AW12)-(AX12)))+2*(((IFERROR(--LEFT(AM12,FIND("-",AM12)-1),""))-(IFERROR(--MID(AM12,FIND("-",AM12)+1,99),"")))=((AW12)-(AX12)))+2*((IFERROR(--LEFT(AM12,FIND("-",AM12)-1),""))=(AW12))+2*((IFERROR(--MID(AM12,FIND("-",AM12)+1,99),""))=(AX12))),"")) -> 5 | AO12: 1-2 | AP12: =IF(OR($C12="",AO12=""),"",IFERROR(IF(AND(IFERROR(--LEFT(AO12,FIND("-",AO12)-1),"")=AW12,IFERROR(--MID(AO12,FIND("-",AO12)+1,99),"")=AX12),10,5*(SIGN((IFERROR(--LEFT(AO12,FIND("-",AO12)-1),""))-(IFERROR(--MID(AO12,FIND("-",AO12)+1,99),"")))=SIGN((AW12)-(AX12)))+2*(((IFERROR(--LEFT(AO12,FIND("-",AO12)-1),""))-(IFERROR(--MID(AO12,FIND("-",AO12)+1,99),"")))=((AW12)-(AX12)))+2*((IFERROR(--LEFT(AO12,FIND("-",AO12)-1),""))=(AW12))+2*((IFERROR(--MID(AO12,FIND("-",AO12)+1,99),""))=(AX12))),"")) -> 0 | AQ12: 0-1 | AR12: =IF(OR($C12="",AQ12=""),"",IFERROR(IF(AND(IFERROR(--LEFT(AQ12,FIND("-",AQ12)-1),"")=AW12,IFERROR(--MID(AQ12,FIND("-",AQ12)+1,99),"")=AX12),10,5*(SIGN((IFERROR(--LEFT(AQ12,FIND("-",AQ12)-1),""))-(IFERROR(--MID(AQ12,FIND("-",AQ12)+1,99),"")))=SIGN((AW12)-(AX12)))+2*(((IFERROR(--LEFT(AQ12,FIND("-",AQ12)-1),""))-(IFERROR(--MID(AQ12,FIND("-",AQ12)+1,99),"")))=((AW12)-(AX12)))+2*((IFERROR(--LEFT(AQ12,FIND("-",AQ12)-1),""))=(AW12))+2*((IFERROR(--MID(AQ12,FIND("-",AQ12)+1,99),""))=(AX12))),"")) -> 2 | AS12: 0-1 | AT12: =IF(OR($C12="",AS12=""),"",IFERROR(IF(AND(IFERROR(--LEFT(AS12,FIND("-",AS12)-1),"")=AW12,IFERROR(--MID(AS12,FIND("-",AS12)+1,99),"")=AX12),10,5*(SIGN((IFERROR(--LEFT(AS12,FIND("-",AS12)-1),""))-(IFERROR(--MID(AS12,FIND("-",AS12)+1,99),"")))=SIGN((AW12)-(AX12)))+2*(((IFERROR(--LEFT(AS12,FIND("-",AS12)-1),""))-(IFERROR(--MID(AS12,FIND("-",AS12)+1,99),"")))=((AW12)-(AX12)))+2*((IFERROR(--LEFT(AS12,FIND("-",AS12)-1),""))=(AW12))+2*((IFERROR(--MID(AS12,FIND("-",AS12)+1,99),""))=(AX12))),"")) -> 2 | AU12: 0-2 | AV12: =IF(OR($C12="",AU12=""),"",IFERROR(IF(AND(IFERROR(--LEFT(AU12,FIND("-",AU12)-1),"")=AW12,IFERROR(--MID(AU12,FIND("-",AU12)+1,99),"")=AX12),10,5*(SIGN((IFERROR(--LEFT(AU12,FIND("-",AU12)-1),""))-(IFERROR(--MID(AU12,FIND("-",AU12)+1,99),"")))=SIGN((AW12)-(AX12)))+2*(((IFERROR(--LEFT(AU12,FIND("-",AU12)-1),""))-(IFERROR(--MID(AU12,FIND("-",AU12)+1,99),"")))=((AW12)-(AX12)))+2*((IFERROR(--LEFT(AU12,FIND("-",AU12)-1),""))=(AW12))+2*((IFERROR(--MID(AU12,FIND("-",AU12)+1,99),""))=(AX12))),"")) -> 0 | AW12: =IF($C12="","",IFERROR(--LEFT($C12,FIND("-",$C12)-1),"")) -> 4 | AX12: =IF($C12="","",IFERROR(--MID($C12,FIND("-",$C12)+1,99),"")) -> 1
A13: 1.875 | B13: Qatar | C13: 1-1 | D13: Zwitserland | E13: 0-2 | F13: =IF(OR($C13="",E13=""),"",IFERROR(IF(AND(IFERROR(--LEFT(E13,FIND("-",E13)-1),"")=AW13,IFERROR(--MID(E13,FIND("-",E13)+1,99),"")=AX13),10,5*(SIGN((IFERROR(--LEFT(E13,FIND("-",E13)-1),""))-(IFERROR(--MID(E13,FIND("-",E13)+1,99),"")))=SIGN((AW13)-(AX13)))+2*(((IFERROR(--LEFT(E13,FIND("-",E13)-1),""))-(IFERROR(--MID(E13,FIND("-",E13)+1,99),"")))=((AW13)-(AX13)))+2*((IFERROR(--LEFT(E13,FIND("-",E13)-1),""))=(AW13))+2*((IFERROR(--MID(E13,FIND("-",E13)+1,99),""))=(AX13))),"")) -> 0 | G13: 1-2 | H13: =IF(OR($C13="",G13=""),"",IFERROR(IF(AND(IFERROR(--LEFT(G13,FIND("-",G13)-1),"")=AW13,IFERROR(--MID(G13,FIND("-",G13)+1,99),"")=AX13),10,5*(SIGN((IFERROR(--LEFT(G13,FIND("-",G13)-1),""))-(IFERROR(--MID(G13,FIND("-",G13)+1,99),"")))=SIGN((AW13)-(AX13)))+2*(((IFERROR(--LEFT(G13,FIND("-",G13)-1),""))-(IFERROR(--MID(G13,FIND("-",G13)+1,99),"")))=((AW13)-(AX13)))+2*((IFERROR(--LEFT(G13,FIND("-",G13)-1),""))=(AW13))+2*((IFERROR(--MID(G13,FIND("-",G13)+1,99),""))=(AX13))),"")) -> 2 | I13: 0-2 | J13: =IF(OR($C13="",I13=""),"",IFERROR(IF(AND(IFERROR(--LEFT(I13,FIND("-",I13)-1),"")=AW13,IFERROR(--MID(I13,FIND("-",I13)+1,99),"")=AX13),10,5*(SIGN((IFERROR(--LEFT(I13,FIND("-",I13)-1),""))-(IFERROR(--MID(I13,FIND("-",I13)+1,99),"")))=SIGN((AW13)-(AX13)))+2*(((IFERROR(--LEFT(I13,FIND("-",I13)-1),""))-(IFERROR(--MID(I13,FIND("-",I13)+1,99),"")))=((AW13)-(AX13)))+2*((IFERROR(--LEFT(I13,FIND("-",I13)-1),""))=(AW13))+2*((IFERROR(--MID(I13,FIND("-",I13)+1,99),""))=(AX13))),"")) -> 0 | K13: 0-2 | L13: =IF(OR($C13="",K13=""),"",IFERROR(IF(AND(IFERROR(--LEFT(K13,FIND("-",K13)-1),"")=AW13,IFERROR(--MID(K13,FIND("-",K13)+1,99),"")=AX13),10,5*(SIGN((IFERROR(--LEFT(K13,FIND("-",K13)-1),""))-(IFERROR(--MID(K13,FIND("-",K13)+1,99),"")))=SIGN((AW13)-(AX13)))+2*(((IFERROR(--LEFT(K13,FIND("-",K13)-1),""))-(IFERROR(--MID(K13,FIND("-",K13)+1,99),"")))=((AW13)-(AX13)))+2*((IFERROR(--LEFT(K13,FIND("-",K13)-1),""))=(AW13))+2*((IFERROR(--MID(K13,FIND("-",K13)+1,99),""))=(AX13))),"")) -> 0 | M13: 0-2 | N13: =IF(OR($C13="",M13=""),"",IFERROR(IF(AND(IFERROR(--LEFT(M13,FIND("-",M13)-1),"")=AW13,IFERROR(--MID(M13,FIND("-",M13)+1,99),"")=AX13),10,5*(SIGN((IFERROR(--LEFT(M13,FIND("-",M13)-1),""))-(IFERROR(--MID(M13,FIND("-",M13)+1,99),"")))=SIGN((AW13)-(AX13)))+2*(((IFERROR(--LEFT(M13,FIND("-",M13)-1),""))-(IFERROR(--MID(M13,FIND("-",M13)+1,99),"")))=((AW13)-(AX13)))+2*((IFERROR(--LEFT(M13,FIND("-",M13)-1),""))=(AW13))+2*((IFERROR(--MID(M13,FIND("-",M13)+1,99),""))=(AX13))),"")) -> 0 | O13: 0-3 | P13: =IF(OR($C13="",O13=""),"",IFERROR(IF(AND(IFERROR(--LEFT(O13,FIND("-",O13)-1),"")=AW13,IFERROR(--MID(O13,FIND("-",O13)+1,99),"")=AX13),10,5*(SIGN((IFERROR(--LEFT(O13,FIND("-",O13)-1),""))-(IFERROR(--MID(O13,FIND("-",O13)+1,99),"")))=SIGN((AW13)-(AX13)))+2*(((IFERROR(--LEFT(O13,FIND("-",O13)-1),""))-(IFERROR(--MID(O13,FIND("-",O13)+1,99),"")))=((AW13)-(AX13)))+2*((IFERROR(--LEFT(O13,FIND("-",O13)-1),""))=(AW13))+2*((IFERROR(--MID(O13,FIND("-",O13)+1,99),""))=(AX13))),"")) -> 0 | Q13: 1-3 | R13: =IF(OR($C13="",Q13=""),"",IFERROR(IF(AND(IFERROR(--LEFT(Q13,FIND("-",Q13)-1),"")=AW13,IFERROR(--MID(Q13,FIND("-",Q13)+1,99),"")=AX13),10,5*(SIGN((IFERROR(--LEFT(Q13,FIND("-",Q13)-1),""))-(IFERROR(--MID(Q13,FIND("-",Q13)+1,99),"")))=SIGN((AW13)-(AX13)))+2*(((IFERROR(--LEFT(Q13,FIND("-",Q13)-1),""))-(IFERROR(--MID(Q13,FIND("-",Q13)+1,99),"")))=((AW13)-(AX13)))+2*((IFERROR(--LEFT(Q13,FIND("-",Q13)-1),""))=(AW13))+2*((IFERROR(--MID(Q13,FIND("-",Q13)+1,99),""))=(AX13))),"")) -> 2 | S13: 2-2 | T13: =IF(OR($C13="",S13=""),"",IFERROR(IF(AND(IFERROR(--LEFT(S13,FIND("-",S13)-1),"")=AW13,IFERROR(--MID(S13,FIND("-",S13)+1,99),"")=AX13),10,5*(SIGN((IFERROR(--LEFT(S13,FIND("-",S13)-1),""))-(IFERROR(--MID(S13,FIND("-",S13)+1,99),"")))=SIGN((AW13)-(AX13)))+2*(((IFERROR(--LEFT(S13,FIND("-",S13)-1),""))-(IFERROR(--MID(S13,FIND("-",S13)+1,99),"")))=((AW13)-(AX13)))+2*((IFERROR(--LEFT(S13,FIND("-",S13)-1),""))=(AW13))+2*((IFERROR(--MID(S13,FIND("-",S13)+1,99),""))=(AX13))),"")) -> 7 | U13: 0-2 | V13: =IF(OR($C13="",U13=""),"",IFERROR(IF(AND(IFERROR(--LEFT(U13,FIND("-",U13)-1),"")=AW13,IFERROR(--MID(U13,FIND("-",U13)+1,99),"")=AX13),10,5*(SIGN((IFERROR(--LEFT(U13,FIND("-",U13)-1),""))-(IFERROR(--MID(U13,FIND("-",U13)+1,99),"")))=SIGN((AW13)-(AX13)))+2*(((IFERROR(--LEFT(U13,FIND("-",U13)-1),""))-(IFERROR(--MID(U13,FIND("-",U13)+1,99),"")))=((AW13)-(AX13)))+2*((IFERROR(--LEFT(U13,FIND("-",U13)-1),""))=(AW13))+2*((IFERROR(--MID(U13,FIND("-",U13)+1,99),""))=(AX13))),"")) -> 0 | W13: 0-2 | X13: =IF(OR($C13="",W13=""),"",IFERROR(IF(AND(IFERROR(--LEFT(W13,FIND("-",W13)-1),"")=AW13,IFERROR(--MID(W13,FIND("-",W13)+1,99),"")=AX13),10,5*(SIGN((IFERROR(--LEFT(W13,FIND("-",W13)-1),""))-(IFERROR(--MID(W13,FIND("-",W13)+1,99),"")))=SIGN((AW13)-(AX13)))+2*(((IFERROR(--LEFT(W13,FIND("-",W13)-1),""))-(IFERROR(--MID(W13,FIND("-",W13)+1,99),"")))=((AW13)-(AX13)))+2*((IFERROR(--LEFT(W13,FIND("-",W13)-1),""))=(AW13))+2*((IFERROR(--MID(W13,FIND("-",W13)+1,99),""))=(AX13))),"")) -> 0 | Y13: 0-2 | Z13: =IF(OR($C13="",Y13=""),"",IFERROR(IF(AND(IFERROR(--LEFT(Y13,FIND("-",Y13)-1),"")=AW13,IFERROR(--MID(Y13,FIND("-",Y13)+1,99),"")=AX13),10,5*(SIGN((IFERROR(--LEFT(Y13,FIND("-",Y13)-1),""))-(IFERROR(--MID(Y13,FIND("-",Y13)+1,99),"")))=SIGN((AW13)-(AX13)))+2*(((IFERROR(--LEFT(Y13,FIND("-",Y13)-1),""))-(IFERROR(--MID(Y13,FIND("-",Y13)+1,99),"")))=((AW13)-(AX13)))+2*((IFERROR(--LEFT(Y13,FIND("-",Y13)-1),""))=(AW13))+2*((IFERROR(--MID(Y13,FIND("-",Y13)+1,99),""))=(AX13))),"")) -> 0 | AA13: 1-2 | AB13: =IF(OR($C13="",AA13=""),"",IFERROR(IF(AND(IFERROR(--LEFT(AA13,FIND("-",AA13)-1),"")=AW13,IFERROR(--MID(AA13,FIND("-",AA13)+1,99),"")=AX13),10,5*(SIGN((IFERROR(--LEFT(AA13,FIND("-",AA13)-1),""))-(IFERROR(--MID(AA13,FIND("-",AA13)+1,99),"")))=SIGN((AW13)-(AX13)))+2*(((IFERROR(--LEFT(AA13,FIND("-",AA13)-1),""))-(IFERROR(--MID(AA13,FIND("-",AA13)+1,99),"")))=((AW13)-(AX13)))+2*((IFERROR(--LEFT(AA13,FIND("-",AA13)-1),""))=(AW13))+2*((IFERROR(--MID(AA13,FIND("-",AA13)+1,99),""))=(AX13))),"")) -> 2 | AC13: 1-3 | AD13: =IF(OR($C13="",AC13=""),"",IFERROR(IF(AND(IFERROR(--LEFT(AC13,FIND("-",AC13)-1),"")=AW13,IFERROR(--MID(AC13,FIND("-",AC13)+1,99),"")=AX13),10,5*(SIGN((IFERROR(--LEFT(AC13,FIND("-",AC13)-1),""))-(IFERROR(--MID(AC13,FIND("-",AC13)+1,99),"")))=SIGN((AW13)-(AX13)))+2*(((IFERROR(--LEFT(AC13,FIND("-",AC13)-1),""))-(IFERROR(--MID(AC13,FIND("-",AC13)+1,99),"")))=((AW13)-(AX13)))+2*((IFERROR(--LEFT(AC13,FIND("-",AC13)-1),""))=(AW13))+2*((IFERROR(--MID(AC13,FIND("-",AC13)+1,99),""))=(AX13))),"")) -> 2 | AE13: 0-2 | AF13: =IF(OR($C13="",AE13=""),"",IFERROR(IF(AND(IFERROR(--LEFT(AE13,FIND("-",AE13)-1),"")=AW13,IFERROR(--MID(AE13,FIND("-",AE13)+1,99),"")=AX13),10,5*(SIGN((IFERROR(--LEFT(AE13,FIND("-",AE13)-1),""))-(IFERROR(--MID(AE13,FIND("-",AE13)+1,99),"")))=SIGN((AW13)-(AX13)))+2*(((IFERROR(--LEFT(AE13,FIND("-",AE13)-1),""))-(IFERROR(--MID(AE13,FIND("-",AE13)+1,99),"")))=((AW13)-(AX13)))+2*((IFERROR(--LEFT(AE13,FIND("-",AE13)-1),""))=(AW13))+2*((IFERROR(--MID(AE13,FIND("-",AE13)+1,99),""))=(AX13))),"")) -> 0 | AG13: 0-2 | AH13: =IF(OR($C13="",AG13=""),"",IFERROR(IF(AND(IFERROR(--LEFT(AG13,FIND("-",AG13)-1),"")=AW13,IFERROR(--MID(AG13,FIND("-",AG13)+1,99),"")=AX13),10,5*(SIGN((IFERROR(--LEFT(AG13,FIND("-",AG13)-1),""))-(IFERROR(--MID(AG13,FIND("-",AG13)+1,99),"")))=SIGN((AW13)-(AX13)))+2*(((IFERROR(--LEFT(AG13,FIND("-",AG13)-1),""))-(IFERROR(--MID(AG13,FIND("-",AG13)+1,99),"")))=((AW13)-(AX13)))+2*((IFERROR(--LEFT(AG13,FIND("-",AG13)-1),""))=(AW13))+2*((IFERROR(--MID(AG13,FIND("-",AG13)+1,99),""))=(AX13))),"")) -> 0 | AI13: 0-3 | AJ13: =IF(OR($C13="",AI13=""),"",IFERROR(IF(AND(IFERROR(--LEFT(AI13,FIND("-",AI13)-1),"")=AW13,IFERROR(--MID(AI13,FIND("-",AI13)+1,99),"")=AX13),10,5*(SIGN((IFERROR(--LEFT(AI13,FIND("-",AI13)-1),""))-(IFERROR(--MID(AI13,FIND("-",AI13)+1,99),"")))=SIGN((AW13)-(AX13)))+2*(((IFERROR(--LEFT(AI13,FIND("-",AI13)-1),""))-(IFERROR(--MID(AI13,FIND("-",AI13)+1,99),"")))=((AW13)-(AX13)))+2*((IFERROR(--LEFT(AI13,FIND("-",AI13)-1),""))=(AW13))+2*((IFERROR(--MID(AI13,FIND("-",AI13)+1,99),""))=(AX13))),"")) -> 0 | AK13: 1-2 | AL13: =IF(OR($C13="",AK13=""),"",IFERROR(IF(AND(IFERROR(--LEFT(AK13,FIND("-",AK13)-1),"")=AW13,IFERROR(--MID(AK13,FIND("-",AK13)+1,99),"")=AX13),10,5*(SIGN((IFERROR(--LEFT(AK13,FIND("-",AK13)-1),""))-(IFERROR(--MID(AK13,FIND("-",AK13)+1,99),"")))=SIGN((AW13)-(AX13)))+2*(((IFERROR(--LEFT(AK13,FIND("-",AK13)-1),""))-(IFERROR(--MID(AK13,FIND("-",AK13)+1,99),"")))=((AW13)-(AX13)))+2*((IFERROR(--LEFT(AK13,FIND("-",AK13)-1),""))=(AW13))+2*((IFERROR(--MID(AK13,FIND("-",AK13)+1,99),""))=(AX13))),"")) -> 2 | AM13: 0-2 | AN13: =IF(OR($C13="",AM13=""),"",IFERROR(IF(AND(IFERROR(--LEFT(AM13,FIND("-",AM13)-1),"")=AW13,IFERROR(--MID(AM13,FIND("-",AM13)+1,99),"")=AX13),10,5*(SIGN((IFERROR(--LEFT(AM13,FIND("-",AM13)-1),""))-(IFERROR(--MID(AM13,FIND("-",AM13)+1,99),"")))=SIGN((AW13)-(AX13)))+2*(((IFERROR(--LEFT(AM13,FIND("-",AM13)-1),""))-(IFERROR(--MID(AM13,FIND("-",AM13)+1,99),"")))=((AW13)-(AX13)))+2*((IFERROR(--LEFT(AM13,FIND("-",AM13)-1),""))=(AW13))+2*((IFERROR(--MID(AM13,FIND("-",AM13)+1,99),""))=(AX13))),"")) -> 0 | AO13: 0-2 | AP13: =IF(OR($C13="",AO13=""),"",IFERROR(IF(AND(IFERROR(--LEFT(AO13,FIND("-",AO13)-1),"")=AW13,IFERROR(--MID(AO13,FIND("-",AO13)+1,99),"")=AX13),10,5*(SIGN((IFERROR(--LEFT(AO13,FIND("-",AO13)-1),""))-(IFERROR(--MID(AO13,FIND("-",AO13)+1,99),"")))=SIGN((AW13)-(AX13)))+2*(((IFERROR(--LEFT(AO13,FIND("-",AO13)-1),""))-(IFERROR(--MID(AO13,FIND("-",AO13)+1,99),"")))=((AW13)-(AX13)))+2*((IFERROR(--LEFT(AO13,FIND("-",AO13)-1),""))=(AW13))+2*((IFERROR(--MID(AO13,FIND("-",AO13)+1,99),""))=(AX13))),"")) -> 0 | AQ13: 0-2 | AR13: =IF(OR($C13="",AQ13=""),"",IFERROR(IF(AND(IFERROR(--LEFT(AQ13,FIND("-",AQ13)-1),"")=AW13,IFERROR(--MID(AQ13,FIND("-",AQ13)+1,99),"")=AX13),10,5*(SIGN((IFERROR(--LEFT(AQ13,FIND("-",AQ13)-1),""))-(IFERROR(--MID(AQ13,FIND("-",AQ13)+1,99),"")))=SIGN((AW13)-(AX13)))+2*(((IFERROR(--LEFT(AQ13,FIND("-",AQ13)-1),""))-(IFERROR(--MID(AQ13,FIND("-",AQ13)+1,99),"")))=((AW13)-(AX13)))+2*((IFERROR(--LEFT(AQ13,FIND("-",AQ13)-1),""))=(AW13))+2*((IFERROR(--MID(AQ13,FIND("-",AQ13)+1,99),""))=(AX13))),"")) -> 0 | AS13: 0-2 | AT13: =IF(OR($C13="",AS13=""),"",IFERROR(IF(AND(IFERROR(--LEFT(AS13,FIND("-",AS13)-1),"")=AW13,IFERROR(--MID(AS13,FIND("-",AS13)+1,99),"")=AX13),10,5*(SIGN((IFERROR(--LEFT(AS13,FIND("-",AS13)-1),""))-(IFERROR(--MID(AS13,FIND("-",AS13)+1,99),"")))=SIGN((AW13)-(AX13)))+2*(((IFERROR(--LEFT(AS13,FIND("-",AS13)-1),""))-(IFERROR(--MID(AS13,FIND("-",AS13)+1,99),"")))=((AW13)-(AX13)))+2*((IFERROR(--LEFT(AS13,FIND("-",AS13)-1),""))=(AW13))+2*((IFERROR(--MID(AS13,FIND("-",AS13)+1,99),""))=(AX13))),"")) -> 0 | AU13: 0-2 | AV13: =IF(OR($C13="",AU13=""),"",IFERROR(IF(AND(IFERROR(--LEFT(AU13,FIND("-",AU13)-1),"")=AW13,IFERROR(--MID(AU13,FIND("-",AU13)+1,99),"")=AX13),10,5*(SIGN((IFERROR(--LEFT(AU13,FIND("-",AU13)-1),""))-(IFERROR(--MID(AU13,FIND("-",AU13)+1,99),"")))=SIGN((AW13)-(AX13)))+2*(((IFERROR(--LEFT(AU13,FIND("-",AU13)-1),""))-(IFERROR(--MID(AU13,FIND("-",AU13)+1,99),"")))=((AW13)-(AX13)))+2*((IFERROR(--LEFT(AU13,FIND("-",AU13)-1),""))=(AW13))+2*((IFERROR(--MID(AU13,FIND("-",AU13)+1,99),""))=(AX13))),"")) -> 0 | AW13: =IF($C13="","",IFERROR(--LEFT($C13,FIND("-",$C13)-1),"")) -> 1 | AX13: =IF($C13="","",IFERROR(--MID($C13,FIND("-",$C13)+1,99),"")) -> 1
AR14: =IF(OR($C14="",AQ14=""),"",IFERROR(IF(AND(IFERROR(--LEFT(AQ14,FIND("-",AQ14)-1),"")=AW14,IFERROR(--MID(AQ14,FIND("-",AQ14)+1,99),"")=AX14),10,5*(SIGN((IFERROR(--LEFT(AQ14,FIND("-",AQ14)-1),""))-(IFERROR(--MID(AQ14,FIND("-",AQ14)+1,99),"")))=SIGN((AW14)-(AX14)))+2*(((IFERROR(--LEFT(AQ14,FIND("-",AQ14)-1),""))-(IFERROR(--MID(AQ14,FIND("-",AQ14)+1,99),"")))=((AW14)-(AX14)))+2*((IFERROR(--LEFT(AQ14,FIND("-",AQ14)-1),""))=(AW14))+2*((IFERROR(--MID(AQ14,FIND("-",AQ14)+1,99),""))=(AX14))),"")) | AT14: =IF(OR($C14="",AS14=""),"",IFERROR(IF(AND(IFERROR(--LEFT(AS14,FIND("-",AS14)-1),"")=AW14,IFERROR(--MID(AS14,FIND("-",AS14)+1,99),"")=AX14),10,5*(SIGN((IFERROR(--LEFT(AS14,FIND("-",AS14)-1),""))-(IFERROR(--MID(AS14,FIND("-",AS14)+1,99),"")))=SIGN((AW14)-(AX14)))+2*(((IFERROR(--LEFT(AS14,FIND("-",AS14)-1),""))-(IFERROR(--MID(AS14,FIND("-",AS14)+1,99),"")))=((AW14)-(AX14)))+2*((IFERROR(--LEFT(AS14,FIND("-",AS14)-1),""))=(AW14))+2*((IFERROR(--MID(AS14,FIND("-",AS14)+1,99),""))=(AX14))),""))
A15: zondag 14 juni 2026
